Workbook

Sheet تعليمات
A1: المشروع القومي للياقة البدنية بالمعاهد الأزهرية - حزمة سجلات التقييم والمتابعة 2026/2027
A2: دليل الاستخدام
A3: م | B3: الشيت | C3: المستوى | D3: الغرض
A4: 1 | B4: تعليمات | C4: الجميع | D4: هذا الشيت
A5: 2 | B5: متابعة المراحل | C5: المنطقة | D5: متابعة مواعيد المراحل الخمس ونسب الإنجاز
A6: 3 | B6: المساطر | C6: الجميع | D6: الدرجات المعيارية (مسطرة القياس) المنقولة من الدليل - تغذي حساب الدرجات تلقائياً
A7: 4 | B7: مسح ابتدائي بنين / إعدادي بنين / ثانوي بنين | C7: المعهد | D7: تسجيل اختبارات كل طالب (حكمان لكل اختبار) وحساب الدرجة والتقدير والترتيب
A8: 5 | B8: مسح ابتدائي بنات / إعدادي بنات | C8: المعهد | D8: نفس الوظيفة لاختبارات البنات
A9: 6 | B9: سجل المنتخبات | C9: المعهد/الإدارة/المنطقة | D9: قوائم منتخبات المعهد (10) والإدارة (10+2) والمنطقة (15)
A10: 7 | B10: الكشف الطبي | C10: المنطقة | D10: استمارة الكشف الطبي للمشاركين قبل التقييم
A11: 8 | B11: لجنة التحكيم | C11: الإدارة/المنطقة | D11: توزيع الحكام وشروط اختيارهم
A12: 9 | B12: بطاقة متابعة الطالب | C12: المعهد | D12: متابعة أداء طلاب الصفوف الأولى (الجناح الأول - التدريب)
A13: 10 | B13: سجل التدريب | C13: المعهد | D13: سجل الحصص والوحدات التدريبية والمحطات
A14: 11 | B14: اكتشاف الموهوبين | C14: المعهد | D14: حصر المتميزين وترشيحهم
A15: 12 | B15: التقييم الذاتي | C15: المعهد | D15: تقييم المعهد لنفسه على 12 بنداً
... A19: 16 | B19: مؤشرات الأداء | C19: المنطقة | D19: المؤشرات التسعة وأدوات قياسها ونسب التحقق
B21: دليل الألوان
B22: خلية إدخال | C22: اكتب فيها فقط
B23: خلية محسوبة | C23: لا تعدّلها (معادلات)
B24: صف مثال | C24: بيانات توضيحية لا تدخل في الترتيب والإجماليات - استبدلها أو احذف محتواها
B26: افتراضات وملاحظات:
B27: - كل الدرجات والمساطر منقولة من دليل المشروع؛ راجع شيت «المساطر» لملاحظات الجداول التي بها لبس.
B28: - التقدير: 1–2 ضعيف، 3–4 مقبول، 5–6 جيد، 7–8 جيد جدا، 9–10 ممتاز (الدليل ص48)؛ ويُحسب لمتوسط درجات الطالب مقرباً.
B29: - الترتيب: مجموع درجات الاختبارات ثم مجموع عدّات (الجري+الجلوس+الانبطاح) عند التعادل؛ الحسم النهائي (الزمن/المسافة/السن) يتم يدوياً.
B30: - حدود التقييم الذاتي والمستهدفات في مؤشرات الأداء مقترحة من إعداد هذه الحزمة وليست من الدليل.

Sheet متابعة المراحل
A1: متابعة مراحل الخطة التنفيذية (المواعيد حسب الدليل ص11–12)
A2: المنطقة الأزهرية: .............. الإدارة التعليمية: .............. المعهد: .............. العام الدراسي: 2026/2027
A3: م | B3: المرحلة | C3: المستوى | D3: البداية المخططة | E3: النهاية المخططة | F3: البداية الفعلية | G3: النهاية الفعلية | H3: الحالة | I3: نسبة الإنجاز | J3: ملاحظات
A4: 1 | B4: المسح الشامل وتعليم الأداء الصحيح (المعهد) - إعدادي وثانوي | C4: المعهد | D4: 46296 | E4: 46317 | H4: =IF(G4<>"",IF(G4<=E4,"أُنجزت في موعدها","أُنجزت متأخرة"),IF(F4<>"",IF(TODAY()>E4,"متأخرة","جارية"),IF(TODAY()>E4,"لم تبدأ - متأخرة","لم تبدأ"))) -> لم تبدأ
A5: 1 | B5: المسح الشامل - المرحلة الابتدائية (طوال العام الدراسي) | C5: المعهد | D5: 46296 | E5: 46568 | H5: =IF(G5<>"",IF(G5<=E5,"أُنجزت في موعدها","أُنجزت متأخرة"),IF(F5<>"",IF(TODAY()>E5,"متأخرة","جارية"),IF(TODAY()>E5,"لم تبدأ - متأخرة","لم تبدأ"))) -> لم تبدأ
A6: 2 | B6: التصفيات واختيار أفضل 10 طلاب لكل مرحلة | C6: الإدارة التعليمية | D6: 46319 | E6: 46338 | H6: =IF(G6<>"",IF(G6<=E6,"أُنجزت في موعدها","أُنجزت متأخرة"),IF(F6<>"",IF(TODAY()>E6,"متأخرة","جارية"),IF(TODAY()>E6,"لم تبدأ - متأخرة","لم تبدأ"))) -> لم تبدأ
A7: 3 | B7: مسابقة اللياقة البدنية - اختيار أفضل 15 لكل مرحلة | C7: المنطقة | D7: 46340 | E7: 46352 | H7: =IF(G7<>"",IF(G7<=E7,"أُنجزت في موعدها","أُنجزت متأخرة"),IF(F7<>"",IF(TODAY()>E7,"متأخرة","جارية"),IF(TODAY()>E7,"لم تبدأ - متأخرة","لم تبدأ"))) -> لم تبدأ
A8: 4 | B8: الوحدات التدريبية لمنتخب المنطقة (3 وحدات) | C8: المنطقة | D8: 46354 | E8: 46366 | H8: =IF(G8<>"",IF(G8<=E8,"أُنجزت في موعدها","أُنجزت متأخرة"),IF(F8<>"",IF(TODAY()>E8,"متأخرة","جارية"),IF(TODAY()>E8,"لم تبدأ - متأخرة","لم تبدأ"))) -> لم تبدأ
A9: 5 | B9: لقاء القمة لأبطال اللياقة البدنية | C9: بيوت الشباب - مركزي | D9: 46409 | E9: 46428 | H9: =IF(G9<>"",IF(G9<=E9,"أُنجزت في موعدها","أُنجزت متأخرة"),IF(F9<>"",IF(TODAY()>E9,"متأخرة","جارية"),IF(TODAY()>E9,"لم تبدأ - متأخرة","لم تبدأ"))) -> لم تبدأ
A11: الدليل يجيز تأجيل فترة التدريب (المرحلة 4) لما بعد امتحانات الفصل الدراسي الأول. حدّث التواريخ المخططة عند التأجيل.

Sheet المساطر
A1: المساطر (الدرجات المعيارية) - منقولة من دليل المشروع ص 21–23 و29–30
A2: الاختبارات التي بالعدّات: الحد الأدنى للعدّات للحصول على الدرجة | الاختبارات الزمنية: الحد الأقصى للزمن (ث) للحصول على الدرجة
A4: مسطرة ابتدائي بنين
A5: الدرجة | B5: الجري في المكان (15ث) - عدد (حد أدنى) | C5: الجلوس من الرقود (30ث) - عدد (حد أدنى) | D5: الانبطاح المائل - عدد (حد أدنى) | E5: الوثب داخل الدوائر المرقمة - زمن (ث) (حد أقصى)
A6: 1 | B6: 12 | C6: 13 | D6: 11 | E6: 7.99
A7: 2 | B7: 14 | C7: 15 | D7: 13 | E7: 7.59
A8: 3 | B8: 16 | C8: 17 | D8: 15 | E8: 7.19
A9: 4 | B9: 18 | C9: 19 | D9: 17 | E9: 6.79
A10: 5 | B10: 20 | C10: 21 | D10: 19 | E10: 6.39
A11: 6 | B11: 22 | C11: 23 | D11: 21 | E11: 5.99
A12: 7 | B12: 24 | C12: 25 | D12: 23 | E12: 5.59
A13: 8 | B13: 26 | C13: 27 | D13: 25 | E13: 5.19
A14: 9 | B14: 28 | C14: 29 | D14: 27 | E14: 4.79
A15: 10 | B15: 30 | C15: 31 | D15: 29 | E15: 4.39
A18: مسطرة إعدادي بنين
A19: الدرجة | B19: الجري في المكان (15ث) - عدد (حد أدنى) | C19: الجلوس من الرقود (30ث) - عدد (حد أدنى) | D19: الانبطاح المائل - عدد (حد أدنى) | E19: الوثب العريض من الثبات - سم (حد أدنى) | F19: الجري الزجزاجي (30م) - زمن (ث) (حد أقصى)
A20: 1 | B20: 24 | C20: 23 | D20: 21 | E20: 131 | F20: 14.49
A21: 2 | B21: 25 | C21: 24 | D21: 23 | E21: 141 | F21: 13.99
A22: 3 | B22: 26 | C22: 25 | D22: 25 | E22: 151 | F22: 13.49
A23: 4 | B23: 27 | C23: 26 | D23: 27 | E23: 161 | F23: 12.99
A24: 5 | B24: 28 | C24: 27 | D24: 29 | E24: 171 | F24: 12.49
A25: 6 | B25: 29 | C25: 28 | D25: 31 | E25: 181 | F25: 11.99
A26: 7 | B26: 30 | C26: 29 | D26: 33 | E26: 191 | F26: 11.49
A27: 8 | B27: 31 | C27: 30 | D27: 35 | E27: 201 | F27: 10.99
A28: 9 | B28: 32 | C28: 31 | D28: 37 | E28: 211 | F28: 10.49
A29: 10 | B29: 33 | C29: 32 | D29: 39 | E29: 221 | F29: 9.99
A32: مسطرة ثانوي بنين
A33: الدرجة | B33: الجري في المكان (15ث) - عدد (حد أدنى) | C33: الجلوس من الرقود (30ث) - عدد (حد أدنى) | D33: الانبطاح المائل - عدد (حد أدنى) | E33: الجري متعدد الجهات - زمن (ث) (حد أقصى) | F33: ثني الجذع من الوقوف - سم (حد أدنى)
A34: 1 | B34: 26 | C34: 25 | D34: 34 | E34: 14.8 | F34: 1
A35: 2 | B35: 27 | C35: 26 | D35: 36 | E35: 14.6 | F35: 3
A36: 3 | B36: 28 | C36: 27 | D36: 38 | E36: 14.4 | F36: 5
A37: 4 | B37: 29 | C37: 28 | D37: 40 | E37: 14.2 | F37: 7
A38: 5 | B38: 30 | C38: 29 | D38: 42 | E38: 14 | F38: 9
A39: 6 | B39: 31 | C39: 30 | D39: 44 | E39: 13.8 | F39: 11
A40: 7 | B40: 32 | C40: 31 | D40: 46 | E40: 13.6 | F40: 13
A41: 8 | B41: 33 | C41: 32 | D41: 48 | E41: 13.4 | F41: 15
A42: 9 | B42: 34 | C42: 33 | D42: 50 | E42: 13.2 | F42: 17
A43: 10 | B43: 35 | C43: 34 | D43: 52 | E43: 13 | F43: 19
A46: مسطرة ابتدائي بنات
A47: الدرجة | B47: الجري في المكان (15ث) - عدد (حد أدنى) | C47: الجلوس من الرقود (30ث) - عدد (حد أدنى) | D47: الانبطاح المائل العالي - عدد (حد أدنى) | E47: الجري الارتدادي - زمن (ث) (حد أقصى) | F47: الوثب داخل الدوائر المرقمة - زمن (ث) (حد أقصى)
...

Sheet اختبارات ابتدائي بنين
A1: سجل اختبارات اللياقة البدنية - ابتدائي بنين
A2: المنطقة الأزهرية: .............. الإدارة التعليمية: .............. المعهد: .............. العام الدراسي: 2026/2027
A3: م | B3: الاسم | C3: تاريخ الميلاد | D3: الصف | E3: الجري في المكان (15ث) - عدد | I3: الجلوس من الرقود (30ث) - عدد | M3: الانبطاح المائل - عدد | Q3: الوثب داخل الدوائر المرقمة - زمن (ث) | U3: إجمالي الدرجات | V3: متوسط الدرجة (من 10) | W3: التقدير | X3: مجموع عدّات (الجري+الجلوس+الانبطاح) | Y3: الترتيب
E4: حكم 1 | F4: حكم 2 | G4: المتوسط | H4: الدرجة | I4: حكم 1 | J4: حكم 2 | K4: المتوسط | L4: الدرجة | M4: حكم 1 | N4: حكم 2 | O4: المتوسط | P4: الدرجة | Q4: محاولة 1 | R4: محاولة 2 | S4: الأفضل | T4: الدرجة
A5: مثال | B5: طالب (مثال) | C5: 2015-03-10 | D5: الثاني | E5: 21 | F5: 22 | G5: =IF(COUNT(E5:F5)=0,"",AVERAGE(E5:F5)) -> 21.5 | H5: =IF(G5="","",SUMPRODUCT(--(G5>=المساطر!$B$6:$B$15))) -> 5 | I5: 23 | J5: 22 | K5: =IF(COUNT(I5:J5)=0,"",AVERAGE(I5:J5)) -> 22.5 | L5: =IF(K5="","",SUMPRODUCT(--(K5>=المساطر!$C$6:$C$15))) -> 5 | M5: 20 | N5: 19 | O5: =IF(COUNT(M5:N5)=0,"",AVERAGE(M5:N5)) -> 19.5 | P5: =IF(O5="","",SUMPRODUCT(--(O5>=المساطر!$D$6:$D$15))) -> 5 | Q5: 5.9 | R5: 6.1 | S5: =IF(COUNT(Q5:R5)=0,"",MIN(Q5:R5)) -> 5.9 | T5: =IF(S5="","",SUMPRODUCT(--(S5<=المساطر!$E$6:$E$15))) -> 6 | U5: =IF(COUNT(H5,L5,P5,T5)=4,SUM(H5,L5,P5,T5),"") -> 21 | V5: =IF(U5="","",U5/4) -> 5.25 | W5: =IF(V5="","",IF(ROUND(V5,0)>=9,"ممتاز",IF(ROUND(V5,0)>=7,"جيد جدا",IF(ROUND(V5,0)>=5,"جيد",IF(ROUND(V5,0)>=3,"مقبول","ضعيف"))))) -> جيد | X5: =IF(COUNT(G5,K5,O5)=3,SUM(G5,K5,O5),"") -> 63.5 | Y5: =IF(U5="","",1+COUNTIF($U$6:$U$45,">"&U5)+COUNTIFS($U$6:$U$45,U5,$X$6:$X$45,">"&X5)) -> 1
A6: 1 | G6: =IF(COUNT(E6:F6)=0,"",AVERAGE(E6:F6)) | H6: =IF(G6="","",SUMPRODUCT(--(G6>=المساطر!$B$6:$B$15))) | K6: =IF(COUNT(I6:J6)=0,"",AVERAGE(I6:J6)) | L6: =IF(K6="","",SUMPRODUCT(--(K6>=المساطر!$C$6:$C$15))) | O6: =IF(COUNT(M6:N6)=0,"",AVERAGE(M6:N6)) | P6: =IF(O6="","",SUMPRODUCT(--(O6>=المساطر!$D$6:$D$15))) | S6: =IF(COUNT(Q6:R6)=0,"",MIN(Q6:R6)) | T6: =IF(S6="","",SUMPRODUCT(--(S6<=المساطر!$E$6:$E$15))) | U6: =IF(COUNT(H6,L6,P6,T6)=4,SUM(H6,L6,P6,T6),"") | V6: =IF(U6="","",U6/4) | W6: =IF(V6="","",IF(ROUND(V6,0)>=9,"ممتاز",IF(ROUND(V6,0)>=7,"جيد جدا",IF(ROUND(V6,0)>=5,"جيد",IF(ROUND(V6,0)>=3,"مقبول","ضعيف"))))) | X6: =IF(COUNT(G6,K6,O6)=3,SUM(G6,K6,O6),"") | Y6: =IF(U6="","",1+COUNTIF($U$6:$U$45,">"&U6)+COUNTIFS($U$6:$U$45,U6,$X$6:$X$45,">"&X6))
A7: 2 | G7: =IF(COUNT(E7:F7)=0,"",AVERAGE(E7:F7)) | H7: =IF(G7="","",SUMPRODUCT(--(G7>=المساطر!$B$6:$B$15))) | K7: =IF(COUNT(I7:J7)=0,"",AVERAGE(I7:J7)) | L7: =IF(K7="","",SUMPRODUCT(--(K7>=المساطر!$C$6:$C$15))) | O7: =IF(COUNT(M7:N7)=0,"",AVERAGE(M7:N7)) | P7: =IF(O7="","",SUMPRODUCT(--(O7>=المساطر!$D$6:$D$15))) | S7: =IF(COUNT(Q7:R7)=0,"",MIN(Q7:R7)) | T7: =IF(S7="","",SUMPRODUCT(--(S7<=المساطر!$E$6:$E$15))) | U7: =IF(COUNT(H7,L7,P7,T7)=4,SUM(H7,L7,P7,T7),"") | V7: =IF(U7="","",U7/4) | W7: =IF(V7="","",IF(ROUND(V7,0)>=9,"ممتاز",IF(ROUND(V7,0)>=7,"جيد جدا",IF(ROUND(V7,0)>=5,"جيد",IF(ROUND(V7,0)>=3,"مقبول","ضعيف"))))) | X7: =IF(COUNT(G7,K7,O7)=3,SUM(G7,K7,O7),"") | Y7: =IF(U7="","",1+COUNTIF($U$6:$U$45,">"&U7)+COUNTIFS($U$6:$U$45,U7,$X$6:$X$45,">"&X7))
A8: 3 | G8: =IF(COUNT(E8:F8)=0,"",AVERAGE(E8:F8)) | H8: =IF(G8="","",SUMPRODUCT(--(G8>=المساطر!$B$6:$B$15))) | K8: =IF(COUNT(I8:J8)=0,"",AVERAGE(I8:J8)) | L8: =IF(K8="","",SUMPRODUCT(--(K8>=المساطر!$C$6:$C$15))) | O8: =IF(COUNT(M8:N8)=0,"",AVERAGE(M8:N8)) | P8: =IF(O8="","",SUMPRODUCT(--(O8>=المساطر!$D$6:$D$15))) | S8: =IF(COUNT(Q8:R8)=0,"",MIN(Q8:R8)) | T8: =IF(S8="","",SUMPRODUCT(--(S8<=المساطر!$E$6:$E$15))) | U8: =IF(COUNT(H8,L8,P8,T8)=4,SUM(H8,L8,P8,T8),"") | V8: =IF(U8="","",U8/4) | W8: =IF(V8="","",IF(ROUND(V8,0)>=9,"ممتاز",IF(ROUND(V8,0)>=7,"جيد جدا",IF(ROUND(V8,0)>=5,"جيد",IF(ROUND(V8,0)>=3,"مقبول","ضعيف"))))) | X8: =IF(COUNT(G8,K8,O8)=3,SUM(G8,K8,O8),"") | Y8: =IF(U8="","",1+COUNTIF($U$6:$U$45,">"&U8)+COUNTIFS($U$6:$U$45,U8,$X$6:$X$45,">"&X8))
A9: 4 | G9: =IF(COUNT(E9:F9)=0,"",AVERAGE(E9:F9)) | H9: =IF(G9="","",SUMPRODUCT(--(G9>=المساطر!$B$6:$B$15))) | K9: =IF(COUNT(I9:J9)=0,"",AVERAGE(I9:J9)) | L9: =IF(K9="","",SUMPRODUCT(--(K9>=المساطر!$C$6:$C$15))) | O9: =IF(COUNT(M9:N9)=0,"",AVERAGE(M9:N9)) | P9: =IF(O9="","",SUMPRODUCT(--(O9>=المساطر!$D$6:$D$15))) | S9: =IF(COUNT(Q9:R9)=0,"",MIN(Q9:R9)) | T9: =IF(S9="","",SUMPRODUCT(--(S9<=المساطر!$E$6:$E$15))) | U9: =IF(COUNT(H9,L9,P9,T9)=4,SUM(H9,L9,P9,T9),"") | V9: =IF(U9="","",U9/4) | W9: =IF(V9="","",IF(ROUND(V9,0)>=9,"ممتاز",IF(ROUND(V9,0)>=7,"جيد جدا",IF(ROUND(V9,0)>=5,"جيد",IF(ROUND(V9,0)>=3,"مقبول","ضعيف"))))) | X9: =IF(COUNT(G9,K9,O9)=3,SUM(G9,K9,O9),"") | Y9: =IF(U9="","",1+COUNTIF($U$6:$U$45,">"&U9)+COUNTIFS($U$6:$U$45,U9,$X$6:$X$45,">"&X9))
A10: 5 | G10: =IF(COUNT(E10:F10)=0,"",AVERAGE(E10:F10)) | H10: =IF(G10="","",SUMPRODUCT(--(G10>=المساطر!$B$6:$B$15))) | K10: =IF(COUNT(I10:J10)=0,"",AVERAGE(I10:J10)) | L10: =IF(K10="","",SUMPRODUCT(--(K10>=المساطر!$C$6:$C$15))) | O10: =IF(COUNT(M10:N10)=0,"",AVERAGE(M10:N10)) | P10: =IF(O10="","",SUMPRODUCT(--(O10>=المساطر!$D$6:$D$15))) | S10: =IF(COUNT(Q10:R10)=0,"",MIN(Q10:R10)) | T10: =IF(S10="","",SUMPRODUCT(--(S10<=المساطر!$E$6:$E$15))) | U10: =IF(COUNT(H10,L10,P10,T10)=4,SUM(H10,L10,P10,T10),"") | V10: =IF(U10="","",U10/4) | W10: =IF(V10="","",IF(ROUND(V10,0)>=9,"ممتاز",IF(ROUND(V10,0)>=7,"جيد جدا",IF(ROUND(V10,0)>=5,"جيد",IF(ROUND(V10,0)>=3,"مقبول","ضعيف"))))) | X10: =IF(COUNT(G10,K10,O10)=3,SUM(G10,K10,O10),"") | Y10: =IF(U10="","",1+COUNTIF($U$6:$U$45,">"&U10)+COUNTIFS($U$6:$U$45,U10,$X$6:$X$45,">"&X10))
A11: 6 | G11: =IF(COUNT(E11:F11)=0,"",AVERAGE(E11:F11)) | H11: =IF(G11="","",SUMPRODUCT(--(G11>=المساطر!$B$6:$B$15))) | K11: =IF(COUNT(I11:J11)=0,"",AVERAGE(I11:J11)) | L11: =IF(K11="","",SUMPRODUCT(--(K11>=المساطر!$C$6:$C$15))) | O11: =IF(COUNT(M11:N11)=0,"",AVERAGE(M11:N11)) | P11: =IF(O11="","",SUMPRODUCT(--(O11>=المساطر!$D$6:$D$15))) | S11: =IF(COUNT(Q11:R11)=0,"",MIN(Q11:R11)) | T11: =IF(S11="","",SUMPRODUCT(--(S11<=المساطر!$E$6:$E$15))) | U11: =IF(COUNT(H11,L11,P11,T11)=4,SUM(H11,L11,P11,T11),"") | V11: =IF(U11="","",U11/4) | W11: =IF(V11="","",IF(ROUND(V11,0)>=9,"ممتاز",IF(ROUND(V11,0)>=7,"جيد جدا",IF(ROUND(V11,0)>=5,"جيد",IF(ROUND(V11,0)>=3,"مقبول","ضعيف"))))) | X11: =IF(COUNT(G11,K11,O11)=3,SUM(G11,K11,O11),"") | Y11: =IF(U11="","",1+COUNTIF($U$6:$U$45,">"&U11)+COUNTIFS($U$6:$U$45,U11,$X$6:$X$45,">"&X11))
A12: 7 | G12: =IF(COUNT(E12:F12)=0,"",AVERAGE(E12:F12)) | H12: =IF(G12="","",SUMPRODUCT(--(G12>=المساطر!$B$6:$B$15))) | K12: =IF(COUNT(I12:J12)=0,"",AVERAGE(I12:J12)) | L12: =IF(K12="","",SUMPRODUCT(--(K12>=المساطر!$C$6:$C$15))) | O12: =IF(COUNT(M12:N12)=0,"",AVERAGE(M12:N12)) | P12: =IF(O12="","",SUMPRODUCT(--(O12>=المساطر!$D$6:$D$15))) | S12: =IF(COUNT(Q12:R12)=0,"",MIN(Q12:R12)) | T12: =IF(S12="","",SUMPRODUCT(--(S12<=المساطر!$E$6:$E$15))) | U12: =IF(COUNT(H12,L12,P12,T12)=4,SUM(H12,L12,P12,T12),"") | V12: =IF(U12="","",U12/4) | W12: =IF(V12="","",IF(ROUND(V12,0)>=9,"ممتاز",IF(ROUND(V12,0)>=7,"جيد جدا",IF(ROUND(V12,0)>=5,"جيد",IF(ROUND(V12,0)>=3,"مقبول","ضعيف"))))) | X12: =IF(COUNT(G12,K12,O12)=3,SUM(G12,K12,O12),"") | Y12: =IF(U12="","",1+COUNTIF($U$6:$U$45,">"&U12)+COUNTIFS($U$6:$U$45,U12,$X$6:$X$45,">"&X12))
A13: 8 | G13: =IF(COUNT(E13:F13)=0,"",AVERAGE(E13:F13)) | H13: =IF(G13="","",SUMPRODUCT(--(G13>=المساطر!$B$6:$B$15))) | K13: =IF(COUNT(I13:J13)=0,"",AVERAGE(I13:J13)) | L13: =IF(K13="","",SUMPRODUCT(--(K13>=المساطر!$C$6:$C$15))) | O13: =IF(COUNT(M13:N13)=0,"",AVERAGE(M13:N13)) | P13: =IF(O13="","",SUMPRODUCT(--(O13>=المساطر!$D$6:$D$15))) | S13: =IF(COUNT(Q13:R13)=0,"",MIN(Q13:R13)) | T13: =IF(S13="","",SUMPRODUCT(--(S13<=المساطر!$E$6:$E$15))) | U13: =IF(COUNT(H13,L13,P13,T13)=4,SUM(H13,L13,P13,T13),"") | V13: =IF(U13="","",U13/4) | W13: =IF(V13="","",IF(ROUND(V13,0)>=9,"ممتاز",IF(ROUND(V13,0)>=7,"جيد جدا",IF(ROUND(V13,0)>=5,"جيد",IF(ROUND(V13,0)>=3,"مقبول","ضعيف"))))) | X13: =IF(COUNT(G13,K13,O13)=3,SUM(G13,K13,O13),"") | Y13: =IF(U13="","",1+COUNTIF($U$6:$U$45,">"&U13)+COUNTIFS($U$6:$U$45,U13,$X$6:$X$45,">"&X13))
A14: 9 | G14: =IF(COUNT(E14:F14)=0,"",AVERAGE(E14:F14)) | H14: =IF(G14="","",SUMPRODUCT(--(G14>=المساطر!$B$6:$B$15))) | K14: =IF(COUNT(I14:J14)=0,"",AVERAGE(I14:J14)) | L14: =IF(K14="","",SUMPRODUCT(--(K14>=المساطر!$C$6:$C$15))) | O14: =IF(COUNT(M14:N14)=0,"",AVERAGE(M14:N14)) | P14: =IF(O14="","",SUMPRODUCT(--(O14>=المساطر!$D$6:$D$15))) | S14: =IF(COUNT(Q14:R14)=0,"",MIN(Q14:R14)) | T14: =IF(S14="","",SUMPRODUCT(--(S14<=المساطر!$E$6:$E$15))) | U14: =IF(COUNT(H14,L14,P14,T14)=4,SUM(H14,L14,P14,T14),"") | V14: =IF(U14="","",U14/4) | W14: =IF(V14="","",IF(ROUND(V14,0)>=9,"ممتاز",IF(ROUND(V14,0)>=7,"جيد جدا",IF(ROUND(V14,0)>=5,"جيد",IF(ROUND(V14,0)>=3,"مقبول","ضعيف"))))) | X14: =IF(COUNT(G14,K14,O14)=3,SUM(G14,K14,O14),"") | Y14: =IF(U14="","",1+COUNTIF($U$6:$U$45,">"&U14)+COUNTIFS($U$6:$U$45,U14,$X$6:$X$45,">"&X14))
A15: 10 | G15: =IF(COUNT(E15:F15)=0,"",AVERAGE(E15:F15)) | H15: =IF(G15="","",SUMPRODUCT(--(G15>=المساطر!$B$6:$B$15))) | K15: =IF(COUNT(I15:J15)=0,"",AVERAGE(I15:J15)) | L15: =IF(K15="","",SUMPRODUCT(--(K15>=المساطر!$C$6:$C$15))) | O15: =IF(COUNT(M15:N15)=0,"",AVERAGE(M15:N15)) | P15: =IF(O15="","",SUMPRODUCT(--(O15>=المساطر!$D$6:$D$15))) | S15: =IF(COUNT(Q15:R15)=0,"",MIN(Q15:R15)) | T15: =IF(S15="","",SUMPRODUCT(--(S15<=المساطر!$E$6:$E$15))) | U15: =IF(COUNT(H15,L15,P15,T15)=4,SUM(H15,L15,P15,T15),"") | V15: =IF(U15="","",U15/4) | W15: =IF(V15="","",IF(ROUND(V15,0)>=9,"ممتاز",IF(ROUND(V15,0)>=7,"جيد جدا",IF(ROUND(V15,0)>=5,"جيد",IF(ROUND(V15,0)>=3,"مقبول","ضعيف"))))) | X15: =IF(COUNT(G15,K15,O15)=3,SUM(G15,K15,O15),"") | Y15: =IF(U15="","",1+COUNTIF($U$6:$U$45,">"&U15)+COUNTIFS($U$6:$U$45,U15,$X$6:$X$45,">"&X15))
A16: 11 | G16: =IF(COUNT(E16:F16)=0,"",AVERAGE(E16:F16)) | H16: =IF(G16="","",SUMPRODUCT(--(G16>=المساطر!$B$6:$B$15))) | K16: =IF(COUNT(I16:J16)=0,"",AVERAGE(I16:J16)) | L16: =IF(K16="","",SUMPRODUCT(--(K16>=المساطر!$C$6:$C$15))) | O16: =IF(COUNT(M16:N16)=0,"",AVERAGE(M16:N16)) | P16: =IF(O16="","",SUMPRODUCT(--(O16>=المساطر!$D$6:$D$15))) | S16: =IF(COUNT(Q16:R16)=0,"",MIN(Q16:R16)) | T16: =IF(S16="","",SUMPRODUCT(--(S16<=المساطر!$E$6:$E$15))) | U16: =IF(COUNT(H16,L16,P16,T16)=4,SUM(H16,L16,P16,T16),"") | V16: =IF(U16="","",U16/4) | W16: =IF(V16="","",IF(ROUND(V16,0)>=9,"ممتاز",IF(ROUND(V16,0)>=7,"جيد جدا",IF(ROUND(V16,0)>=5,"جيد",IF(ROUND(V16,0)>=3,"مقبول","ضعيف"))))) | X16: =IF(COUNT(G16,K16,O16)=3,SUM(G16,K16,O16),"") | Y16: =IF(U16="","",1+COUNTIF($U$6:$U$45,">"&U16)+COUNTIFS($U$6:$U$45,U16,$X$6:$X$45,">"&X16))
A17: 12 | G17: =IF(COUNT(E17:F17)=0,"",AVERAGE(E17:F17)) | H17: =IF(G17="","",SUMPRODUCT(--(G17>=المساطر!$B$6:$B$15))) | K17: =IF(COUNT(I17:J17)=0,"",AVERAGE(I17:J17)) | L17: =IF(K17="","",SUMPRODUCT(--(K17>=المساطر!$C$6:$C$15))) | O17: =IF(COUNT(M17:N17)=0,"",AVERAGE(M17:N17)) | P17: =IF(O17="","",SUMPRODUCT(--(O17>=المساطر!$D$6:$D$15))) | S17: =IF(COUNT(Q17:R17)=0,"",MIN(Q17:R17)) | T17: =IF(S17="","",SUMPRODUCT(--(S17<=المساطر!$E$6:$E$15))) | U17: =IF(COUNT(H17,L17,P17,T17)=4,SUM(H17,L17,P17,T17),"") | V17: =IF(U17="","",U17/4) | W17: =IF(V17="","",IF(ROUND(V17,0)>=9,"ممتاز",IF(ROUND(V17,0)>=7,"جيد جدا",IF(ROUND(V17,0)>=5,"جيد",IF(ROUND(V17,0)>=3,"مقبول","ضعيف"))))) | X17: =IF(COUNT(G17,K17,O17)=3,SUM(G17,K17,O17),"") | Y17: =IF(U17="","",1+COUNTIF($U$6:$U$45,">"&U17)+COUNTIFS($U$6:$U$45,U17,$X$6:$X$45,">"&X17))
... A45: 40 | G45: =IF(COUNT(E45:F45)=0,"",AVERAGE(E45:F45)) | H45: =IF(G45="","",SUMPRODUCT(--(G45>=المساطر!$B$6:$B$15))) | K45: =IF(COUNT(I45:J45)=0,"",AVERAGE(I45:J45)) | L45: =IF(K45="","",SUMPRODUCT(--(K45>=المساطر!$C$6:$C$15))) | O45: =IF(COUNT(M45:N45)=0,"",AVERAGE(M45:N45)) | P45: =IF(O45="","",SUMPRODUCT(--(O45>=المساطر!$D$6:$D$15))) | S45: =IF(COUNT(Q45:R45)=0,"",MIN(Q45:R45)) | T45: =IF(S45="","",SUMPRODUCT(--(S45<=المساطر!$E$6:$E$15))) | U45: =IF(COUNT(H45,L45,P45,T45)=4,SUM(H45,L45,P45,T45),"") | V45: =IF(U45="","",U45/4) | W45: =IF(V45="","",IF(ROUND(V45,0)>=9,"ممتاز",IF(ROUND(V45,0)>=7,"جيد جدا",IF(ROUND(V45,0)>=5,"جيد",IF(ROUND(V45,0)>=3,"مقبول","ضعيف"))))) | X45: =IF(COUNT(G45,K45,O45)=3,SUM(G45,K45,O45),"") | Y45: =IF(U45="","",1+COUNTIF($U$6:$U$45,">"&U45)+COUNTIFS($U$6:$U$45,U45,$X$6:$X$45,">"&X45))
A47: تعليمات: صف «مثال» لا يدخل في الترتيب. أدخل عدّات الحكمين أو المحاولات في الخلايا الصفراء فقط. الاختبارات الزمنية: سجّل الزمن النهائي بعد إضافة ثواني العقوبات، واترك المحاولة الفاشلة فارغة. التعادل في الترتيب يُحسم بمجموع العدّات ثم الأقل زمناً/الأكبر مسافة ثم الأصغر سناً (يدوياً).

Sheet اختبارات إعدادي بنين
A1: سجل اختبارات اللياقة البدنية - إعدادي بنين
A2: المنطقة الأزهرية: .............. الإدارة التعليمية: .............. المعهد: .............. العام الدراسي: 2026/2027
A3: م | B3: الاسم | C3: تاريخ الميلاد | D3: الصف | E3: الجري في المكان (15ث) - عدد | I3: الجلوس من الرقود (30ث) - عدد | M3: الانبطاح المائل - عدد | Q3: الوثب العريض من الثبات - سم | U3: الجري الزجزاجي (30م) - زمن (ث) | Y3: إجمالي الدرجات | Z3: متوسط الدرجة (من 10) | AA3: التقدير | AB3: مجموع عدّات (الجري+الجلوس+الانبطاح) | AC3: الترتيب
E4: حكم 1 | F4: حكم 2 | G4: المتوسط | H4: الدرجة | I4: حكم 1 | J4: حكم 2 | K4: المتوسط | L4: الدرجة | M4: حكم 1 | N4: حكم 2 | O4: المتوسط | P4: الدرجة | Q4: محاولة 1 | R4: محاولة 2 | S4: الأفضل | T4: الدرجة | U4: محاولة 1 | V4: محاولة 2 | W4: الأفضل | X4: الدرجة
A5: مثال | B5: طالب (مثال) | C5: 2015-03-10 | D5: الثاني | E5: 28 | F5: 29 | G5: =IF(COUNT(E5:F5)=0,"",AVERAGE(E5:F5)) -> 28.5 | H5: =IF(G5="","",SUMPRODUCT(--(G5>=المساطر!$B$20:$B$29))) -> 5 | I5: 27 | J5: 27 | K5: =IF(COUNT(I5:J5)=0,"",AVERAGE(I5:J5)) -> 27 | L5: =IF(K5="","",SUMPRODUCT(--(K5>=المساطر!$C$20:$C$29))) -> 5 | M5: 25 | N5: 26 | O5: =IF(COUNT(M5:N5)=0,"",AVERAGE(M5:N5)) -> 25.5 | P5: =IF(O5="","",SUMPRODUCT(--(O5>=المساطر!$D$20:$D$29))) -> 3 | Q5: 200 | R5: 205 | S5: =IF(COUNT(Q5:R5)=0,"",MAX(Q5:R5)) -> 205 | T5: =IF(S5="","",SUMPRODUCT(--(S5>=المساطر!$E$20:$E$29))) -> 8 | U5: 11.4 | V5: 11.9 | W5: =IF(COUNT(U5:V5)=0,"",MIN(U5:V5)) -> 11.4 | X5: =IF(W5="","",SUMPRODUCT(--(W5<=المساطر!$F$20:$F$29))) -> 7 | Y5: =IF(COUNT(H5,L5,P5,T5,X5)=5,SUM(H5,L5,P5,T5,X5),"") -> 28 | Z5: =IF(Y5="","",Y5/5) -> 5.6 | AA5: =IF(Z5="","",IF(ROUND(Z5,0)>=9,"ممتاز",IF(ROUND(Z5,0)>=7,"جيد جدا",IF(ROUND(Z5,0)>=5,"جيد",IF(ROUND(Z5,0)>=3,"مقبول","ضعيف"))))) -> جيد | AB5: =IF(COUNT(G5,K5,O5)=3,SUM(G5,K5,O5),"") -> 81 | AC5: =IF(Y5="","",1+COUNTIF($Y$6:$Y$45,">"&Y5)+COUNTIFS($Y$6:$Y$45,Y5,$AB$6:$AB$45,">"&AB5)) -> 1
A6: 1 | G6: =IF(COUNT(E6:F6)=0,"",AVERAGE(E6:F6)) | H6: =IF(G6="","",SUMPRODUCT(--(G6>=المساطر!$B$20:$B$29))) | K6: =IF(COUNT(I6:J6)=0,"",AVERAGE(I6:J6)) | L6: =IF(K6="","",SUMPRODUCT(--(K6>=المساطر!$C$20:$C$29))) | O6: =IF(COUNT(M6:N6)=0,"",AVERAGE(M6:N6)) | P6: =IF(O6="","",SUMPRODUCT(--(O6>=المساطر!$D$20:$D$29))) | S6: =IF(COUNT(Q6:R6)=0,"",MAX(Q6:R6)) | T6: =IF(S6="","",SUMPRODUCT(--(S6>=المساطر!$E$20:$E$29))) | W6: =IF(COUNT(U6:V6)=0,"",MIN(U6:V6)) | X6: =IF(W6="","",SUMPRODUCT(--(W6<=المساطر!$F$20:$F$29))) | Y6: =IF(COUNT(H6,L6,P6,T6,X6)=5,SUM(H6,L6,P6,T6,X6),"") | Z6: =IF(Y6="","",Y6/5) | AA6: =IF(Z6="","",IF(ROUND(Z6,0)>=9,"ممتاز",IF(ROUND(Z6,0)>=7,"جيد جدا",IF(ROUND(Z6,0)>=5,"جيد",IF(ROUND(Z6,0)>=3,"مقبول","ضعيف"))))) | AB6: =IF(COUNT(G6,K6,O6)=3,SUM(G6,K6,O6),"") | AC6: =IF(Y6="","",1+COUNTIF($Y$6:$Y$45,">"&Y6)+COUNTIFS($Y$6:$Y$45,Y6,$AB$6:$AB$45,">"&AB6))
A7: 2 | G7: =IF(COUNT(E7:F7)=0,"",AVERAGE(E7:F7)) | H7: =IF(G7="","",SUMPRODUCT(--(G7>=المساطر!$B$20:$B$29))) | K7: =IF(COUNT(I7:J7)=0,"",AVERAGE(I7:J7)) | L7: =IF(K7="","",SUMPRODUCT(--(K7>=المساطر!$C$20:$C$29))) | O7: =IF(COUNT(M7:N7)=0,"",AVERAGE(M7:N7)) | P7: =IF(O7="","",SUMPRODUCT(--(O7>=المساطر!$D$20:$D$29))) | S7: =IF(COUNT(Q7:R7)=0,"",MAX(Q7:R7)) | T7: =IF(S7="","",SUMPRODUCT(--(S7>=المساطر!$E$20:$E$29))) | W7: =IF(COUNT(U7:V7)=0,"",MIN(U7:V7)) | X7: =IF(W7="","",SUMPRODUCT(--(W7<=المساطر!$F$20:$F$29))) | Y7: =IF(COUNT(H7,L7,P7,T7,X7)=5,SUM(H7,L7,P7,T7,X7),"") | Z7: =IF(Y7="","",Y7/5) | AA7: =IF(Z7="","",IF(ROUND(Z7,0)>=9,"ممتاز",IF(ROUND(Z7,0)>=7,"جيد جدا",IF(ROUND(Z7,0)>=5,"جيد",IF(ROUND(Z7,0)>=3,"مقبول","ضعيف"))))) | AB7: =IF(COUNT(G7,K7,O7)=3,SUM(G7,K7,O7),"") | AC7: =IF(Y7="","",1+COUNTIF($Y$6:$Y$45,">"&Y7)+COUNTIFS($Y$6:$Y$45,Y7,$AB$6:$AB$45,">"&AB7))
A8: 3 | G8: =IF(COUNT(E8:F8)=0,"",AVERAGE(E8:F8)) | H8: =IF(G8="","",SUMPRODUCT(--(G8>=المساطر!$B$20:$B$29))) | K8: =IF(COUNT(I8:J8)=0,"",AVERAGE(I8:J8)) | L8: =IF(K8="","",SUMPRODUCT(--(K8>=المساطر!$C$20:$C$29))) | O8: =IF(COUNT(M8:N8)=0,"",AVERAGE(M8:N8)) | P8: =IF(O8="","",SUMPRODUCT(--(O8>=المساطر!$D$20:$D$29))) | S8: =IF(COUNT(Q8:R8)=0,"",MAX(Q8:R8)) | T8: =IF(S8="","",SUMPRODUCT(--(S8>=المساطر!$E$20:$E$29))) | W8: =IF(COUNT(U8:V8)=0,"",MIN(U8:V8)) | X8: =IF(W8="","",SUMPRODUCT(--(W8<=المساطر!$F$20:$F$29))) | Y8: =IF(COUNT(H8,L8,P8,T8,X8)=5,SUM(H8,L8,P8,T8,X8),"") | Z8: =IF(Y8="","",Y8/5) | AA8: =IF(Z8="","",IF(ROUND(Z8,0)>=9,"ممتاز",IF(ROUND(Z8,0)>=7,"جيد جدا",IF(ROUND(Z8,0)>=5,"جيد",IF(ROUND(Z8,0)>=3,"مقبول","ضعيف"))))) | AB8: =IF(COUNT(G8,K8,O8)=3,SUM(G8,K8,O8),"") | AC8: =IF(Y8="","",1+COUNTIF($Y$6:$Y$45,">"&Y8)+COUNTIFS($Y$6:$Y$45,Y8,$AB$6:$AB$45,">"&AB8))
A9: 4 | G9: =IF(COUNT(E9:F9)=0,"",AVERAGE(E9:F9)) | H9: =IF(G9="","",SUMPRODUCT(--(G9>=المساطر!$B$20:$B$29))) | K9: =IF(COUNT(I9:J9)=0,"",AVERAGE(I9:J9)) | L9: =IF(K9="","",SUMPRODUCT(--(K9>=المساطر!$C$20:$C$29))) | O9: =IF(COUNT(M9:N9)=0,"",AVERAGE(M9:N9)) | P9: =IF(O9="","",SUMPRODUCT(--(O9>=المساطر!$D$20:$D$29))) | S9: =IF(COUNT(Q9:R9)=0,"",MAX(Q9:R9)) | T9: =IF(S9="","",SUMPRODUCT(--(S9>=المساطر!$E$20:$E$29))) | W9: =IF(COUNT(U9:V9)=0,"",MIN(U9:V9)) | X9: =IF(W9="","",SUMPRODUCT(--(W9<=المساطر!$F$20:$F$29))) | Y9: =IF(COUNT(H9,L9,P9,T9,X9)=5,SUM(H9,L9,P9,T9,X9),"") | Z9: =IF(Y9="","",Y9/5) | AA9: =IF(Z9="","",IF(ROUND(Z9,0)>=9,"ممتاز",IF(ROUND(Z9,0)>=7,"جيد جدا",IF(ROUND(Z9,0)>=5,"جيد",IF(ROUND(Z9,0)>=3,"مقبول","ضعيف"))))) | AB9: =IF(COUNT(G9,K9,O9)=3,SUM(G9,K9,O9),"") | AC9: =IF(Y9="","",1+COUNTIF($Y$6:$Y$45,">"&Y9)+COUNTIFS($Y$6:$Y$45,Y9,$AB$6:$AB$45,">"&AB9))
A10: 5 | G10: =IF(COUNT(E10:F10)=0,"",AVERAGE(E10:F10)) | H10: =IF(G10="","",SUMPRODUCT(--(G10>=المساطر!$B$20:$B$29))) | K10: =IF(COUNT(I10:J10)=0,"",AVERAGE(I10:J10)) | L10: =IF(K10="","",SUMPRODUCT(--(K10>=المساطر!$C$20:$C$29))) | O10: =IF(COUNT(M10:N10)=0,"",AVERAGE(M10:N10)) | P10: =IF(O10="","",SUMPRODUCT(--(O10>=المساطر!$D$20:$D$29))) | S10: =IF(COUNT(Q10:R10)=0,"",MAX(Q10:R10)) | T10: =IF(S10="","",SUMPRODUCT(--(S10>=المساطر!$E$20:$E$29))) | W10: =IF(COUNT(U10:V10)=0,"",MIN(U10:V10)) | X10: =IF(W10="","",SUMPRODUCT(--(W10<=المساطر!$F$20:$F$29))) | Y10: =IF(COUNT(H10,L10,P10,T10,X10)=5,SUM(H10,L10,P10,T10,X10),"") | Z10: =IF(Y10="","",Y10/5) | AA10: =IF(Z10="","",IF(ROUND(Z10,0)>=9,"ممتاز",IF(ROUND(Z10,0)>=7,"جيد جدا",IF(ROUND(Z10,0)>=5,"جيد",IF(ROUND(Z10,0)>=3,"مقبول","ضعيف"))))) | AB10: =IF(COUNT(G10,K10,O10)=3,SUM(G10,K10,O10),"") | AC10: =IF(Y10="","",1+COUNTIF($Y$6:$Y$45,">"&Y10)+COUNTIFS($Y$6:$Y$45,Y10,$AB$6:$AB$45,">"&AB10))
A11: 6 | G11: =IF(COUNT(E11:F11)=0,"",AVERAGE(E11:F11)) | H11: =IF(G11="","",SUMPRODUCT(--(G11>=المساطر!$B$20:$B$29))) | K11: =IF(COUNT(I11:J11)=0,"",AVERAGE(I11:J11)) | L11: =IF(K11="","",SUMPRODUCT(--(K11>=المساطر!$C$20:$C$29))) | O11: =IF(COUNT(M11:N11)=0,"",AVERAGE(M11:N11)) | P11: =IF(O11="","",SUMPRODUCT(--(O11>=المساطر!$D$20:$D$29))) | S11: =IF(COUNT(Q11:R11)=0,"",MAX(Q11:R11)) | T11: =IF(S11="","",SUMPRODUCT(--(S11>=المساطر!$E$20:$E$29))) | W11: =IF(COUNT(U11:V11)=0,"",MIN(U11:V11)) | X11: =IF(W11="","",SUMPRODUCT(--(W11<=المساطر!$F$20:$F$29))) | Y11: =IF(COUNT(H11,L11,P11,T11,X11)=5,SUM(H11,L11,P11,T11,X11),"") | Z11: =IF(Y11="","",Y11/5) | AA11: =IF(Z11="","",IF(ROUND(Z11,0)>=9,"ممتاز",IF(ROUND(Z11,0)>=7,"جيد جدا",IF(ROUND(Z11,0)>=5,"جيد",IF(ROUND(Z11,0)>=3,"مقبول","ضعيف"))))) | AB11: =IF(COUNT(G11,K11,O11)=3,SUM(G11,K11,O11),"") | AC11: =IF(Y11="","",1+COUNTIF($Y$6:$Y$45,">"&Y11)+COUNTIFS($Y$6:$Y$45,Y11,$AB$6:$AB$45,">"&AB11))
A12: 7 | G12: =IF(COUNT(E12:F12)=0,"",AVERAGE(E12:F12)) | H12: =IF(G12="","",SUMPRODUCT(--(G12>=المساطر!$B$20:$B$29))) | K12: =IF(COUNT(I12:J12)=0,"",AVERAGE(I12:J12)) | L12: =IF(K12="","",SUMPRODUCT(--(K12>=المساطر!$C$20:$C$29))) | O12: =IF(COUNT(M12:N12)=0,"",AVERAGE(M12:N12)) | P12: =IF(O12="","",SUMPRODUCT(--(O12>=المساطر!$D$20:$D$29))) | S12: =IF(COUNT(Q12:R12)=0,"",MAX(Q12:R12)) | T12: =IF(S12="","",SUMPRODUCT(--(S12>=المساطر!$E$20:$E$29))) | W12: =IF(COUNT(U12:V12)=0,"",MIN(U12:V12)) | X12: =IF(W12="","",SUMPRODUCT(--(W12<=المساطر!$F$20:$F$29))) | Y12: =IF(COUNT(H12,L12,P12,T12,X12)=5,SUM(H12,L12,P12,T12,X12),"") | Z12: =IF(Y12="","",Y12/5) | AA12: =IF(Z12="","",IF(ROUND(Z12,0)>=9,"ممتاز",IF(ROUND(Z12,0)>=7,"جيد جدا",IF(ROUND(Z12,0)>=5,"جيد",IF(ROUND(Z12,0)>=3,"مقبول","ضعيف"))))) | AB12: =IF(COUNT(G12,K12,O12)=3,SUM(G12,K12,O12),"") | AC12: =IF(Y12="","",1+COUNTIF($Y$6:$Y$45,">"&Y12)+COUNTIFS($Y$6:$Y$45,Y12,$AB$6:$AB$45,">"&AB12))
A13: 8 | G13: =IF(COUNT(E13:F13)=0,"",AVERAGE(E13:F13)) | H13: =IF(G13="","",SUMPRODUCT(--(G13>=المساطر!$B$20:$B$29))) | K13: =IF(COUNT(I13:J13)=0,"",AVERAGE(I13:J13)) | L13: =IF(K13="","",SUMPRODUCT(--(K13>=المساطر!$C$20:$C$29))) | O13: =IF(COUNT(M13:N13)=0,"",AVERAGE(M13:N13)) | P13: =IF(O13="","",SUMPRODUCT(--(O13>=المساطر!$D$20:$D$29))) | S13: =IF(COUNT(Q13:R13)=0,"",MAX(Q13:R13)) | T13: =IF(S13="","",SUMPRODUCT(--(S13>=المساطر!$E$20:$E$29))) | W13: =IF(COUNT(U13:V13)=0,"",MIN(U13:V13)) | X13: =IF(W13="","",SUMPRODUCT(--(W13<=المساطر!$F$20:$F$29))) | Y13: =IF(COUNT(H13,L13,P13,T13,X13)=5,SUM(H13,L13,P13,T13,X13),"") | Z13: =IF(Y13="","",Y13/5) | AA13: =IF(Z13="","",IF(ROUND(Z13,0)>=9,"ممتاز",IF(ROUND(Z13,0)>=7,"جيد جدا",IF(ROUND(Z13,0)>=5,"جيد",IF(ROUND(Z13,0)>=3,"مقبول","ضعيف"))))) | AB13: =IF(COUNT(G13,K13,O13)=3,SUM(G13,K13,O13),"") | AC13: =IF(Y13="","",1+COUNTIF($Y$6:$Y$45,">"&Y13)+COUNTIFS($Y$6:$Y$45,Y13,$AB$6:$AB$45,">"&AB13))
A14: 9 | G14: =IF(COUNT(E14:F14)=0,"",AVERAGE(E14:F14)) | H14: =IF(G14="","",SUMPRODUCT(--(G14>=المساطر!$B$20:$B$29))) | K14: =IF(COUNT(I14:J14)=0,"",AVERAGE(I14:J14)) | L14: =IF(K14="","",SUMPRODUCT(--(K14>=المساطر!$C$20:$C$29))) | O14: =IF(COUNT(M14:N14)=0,"",AVERAGE(M14:N14)) | P14: =IF(O14="","",SUMPRODUCT(--(O14>=المساطر!$D$20:$D$29))) | S14: =IF(COUNT(Q14:R14)=0,"",MAX(Q14:R14)) | T14: =IF(S14="","",SUMPRODUCT(--(S14>=المساطر!$E$20:$E$29))) | W14: =IF(COUNT(U14:V14)=0,"",MIN(U14:V14)) | X14: =IF(W14="","",SUMPRODUCT(--(W14<=المساطر!$F$20:$F$29))) | Y14: =IF(COUNT(H14,L14,P14,T14,X14)=5,SUM(H14,L14,P14,T14,X14),"") | Z14: =IF(Y14="","",Y14/5) | AA14: =IF(Z14="","",IF(ROUND(Z14,0)>=9,"ممتاز",IF(ROUND(Z14,0)>=7,"جيد جدا",IF(ROUND(Z14,0)>=5,"جيد",IF(ROUND(Z14,0)>=3,"مقبول","ضعيف"))))) | AB14: =IF(COUNT(G14,K14,O14)=3,SUM(G14,K14,O14),"") | AC14: =IF(Y14="","",1+COUNTIF($Y$6:$Y$45,">"&Y14)+COUNTIFS($Y$6:$Y$45,Y14,$AB$6:$AB$45,">"&AB14))
A15: 10 | G15: =IF(COUNT(E15:F15)=0,"",AVERAGE(E15:F15)) | H15: =IF(G15="","",SUMPRODUCT(--(G15>=المساطر!$B$20:$B$29))) | K15: =IF(COUNT(I15:J15)=0,"",AVERAGE(I15:J15)) | L15: =IF(K15="","",SUMPRODUCT(--(K15>=المساطر!$C$20:$C$29))) | O15: =IF(COUNT(M15:N15)=0,"",AVERAGE(M15:N15)) | P15: =IF(O15="","",SUMPRODUCT(--(O15>=المساطر!$D$20:$D$29))) | S15: =IF(COUNT(Q15:R15)=0,"",MAX(Q15:R15)) | T15: =IF(S15="","",SUMPRODUCT(--(S15>=المساطر!$E$20:$E$29))) | W15: =IF(COUNT(U15:V15)=0,"",MIN(U15:V15)) | X15: =IF(W15="","",SUMPRODUCT(--(W15<=المساطر!$F$20:$F$29))) | Y15: =IF(COUNT(H15,L15,P15,T15,X15)=5,SUM(H15,L15,P15,T15,X15),"") | Z15: =IF(Y15="","",Y15/5) | AA15: =IF(Z15="","",IF(ROUND(Z15,0)>=9,"ممتاز",IF(ROUND(Z15,0)>=7,"جيد جدا",IF(ROUND(Z15,0)>=5,"جيد",IF(ROUND(Z15,0)>=3,"مقبول","ضعيف"))))) | AB15: =IF(COUNT(G15,K15,O15)=3,SUM(G15,K15,O15),"") | AC15: =IF(Y15="","",1+COUNTIF($Y$6:$Y$45,">"&Y15)+COUNTIFS($Y$6:$Y$45,Y15,$AB$6:$AB$45,">"&AB15))
A16: 11 | G16: =IF(COUNT(E16:F16)=0,"",AVERAGE(E16:F16)) | H16: =IF(G16="","",SUMPRODUCT(--(G16>=المساطر!$B$20:$B$29))) | K16: =IF(COUNT(I16:J16)=0,"",AVERAGE(I16:J16)) | L16: =IF(K16="","",SUMPRODUCT(--(K16>=المساطر!$C$20:$C$29))) | O16: =IF(COUNT(M16:N16)=0,"",AVERAGE(M16:N16)) | P16: =IF(O16="","",SUMPRODUCT(--(O16>=المساطر!$D$20:$D$29))) | S16: =IF(COUNT(Q16:R16)=0,"",MAX(Q16:R16)) | T16: =IF(S16="","",SUMPRODUCT(--(S16>=المساطر!$E$20:$E$29))) | W16: =IF(COUNT(U16:V16)=0,"",MIN(U16:V16)) | X16: =IF(W16="","",SUMPRODUCT(--(W16<=المساطر!$F$20:$F$29))) | Y16: =IF(COUNT(H16,L16,P16,T16,X16)=5,SUM(H16,L16,P16,T16,X16),"") | Z16: =IF(Y16="","",Y16/5) | AA16: =IF(Z16="","",IF(ROUND(Z16,0)>=9,"ممتاز",IF(ROUND(Z16,0)>=7,"جيد جدا",IF(ROUND(Z16,0)>=5,"جيد",IF(ROUND(Z16,0)>=3,"مقبول","ضعيف"))))) | AB16: =IF(COUNT(G16,K16,O16)=3,SUM(G16,K16,O16),"") | AC16: =IF(Y16="","",1+COUNTIF($Y$6:$Y$45,">"&Y16)+COUNTIFS($Y$6:$Y$45,Y16,$AB$6:$AB$45,">"&AB16))
A17: 12 | G17: =IF(COUNT(E17:F17)=0,"",AVERAGE(E17:F17)) | H17: =IF(G17="","",SUMPRODUCT(--(G17>=المساطر!$B$20:$B$29))) | K17: =IF(COUNT(I17:J17)=0,"",AVERAGE(I17:J17)) | L17: =IF(K17="","",SUMPRODUCT(--(K17>=المساطر!$C$20:$C$29))) | O17: =IF(COUNT(M17:N17)=0,"",AVERAGE(M17:N17)) | P17: =IF(O17="","",SUMPRODUCT(--(O17>=المساطر!$D$20:$D$29))) | S17: =IF(COUNT(Q17:R17)=0,"",MAX(Q17:R17)) | T17: =IF(S17="","",SUMPRODUCT(--(S17>=المساطر!$E$20:$E$29))) | W17: =IF(COUNT(U17:V17)=0,"",MIN(U17:V17)) | X17: =IF(W17="","",SUMPRODUCT(--(W17<=المساطر!$F$20:$F$29))) | Y17: =IF(COUNT(H17,L17,P17,T17,X17)=5,SUM(H17,L17,P17,T17,X17),"") | Z17: =IF(Y17="","",Y17/5) | AA17: =IF(Z17="","",IF(ROUND(Z17,0)>=9,"ممتاز",IF(ROUND(Z17,0)>=7,"جيد جدا",IF(ROUND(Z17,0)>=5,"جيد",IF(ROUND(Z17,0)>=3,"مقبول","ضعيف"))))) | AB17: =IF(COUNT(G17,K17,O17)=3,SUM(G17,K17,O17),"") | AC17: =IF(Y17="","",1+COUNTIF($Y$6:$Y$45,">"&Y17)+COUNTIFS($Y$6:$Y$45,Y17,$AB$6:$AB$45,">"&AB17))
... A45: 40 | G45: =IF(COUNT(E45:F45)=0,"",AVERAGE(E45:F45)) | H45: =IF(G45="","",SUMPRODUCT(--(G45>=المساطر!$B$20:$B$29))) | K45: =IF(COUNT(I45:J45)=0,"",AVERAGE(I45:J45)) | L45: =IF(K45="","",SUMPRODUCT(--(K45>=المساطر!$C$20:$C$29))) | O45: =IF(COUNT(M45:N45)=0,"",AVERAGE(M45:N45)) | P45: =IF(O45="","",SUMPRODUCT(--(O45>=المساطر!$D$20:$D$29))) | S45: =IF(COUNT(Q45:R45)=0,"",MAX(Q45:R45)) | T45: =IF(S45="","",SUMPRODUCT(--(S45>=المساطر!$E$20:$E$29))) | W45: =IF(COUNT(U45:V45)=0,"",MIN(U45:V45)) | X45: =IF(W45="","",SUMPRODUCT(--(W45<=المساطر!$F$20:$F$29))) | Y45: =IF(COUNT(H45,L45,P45,T45,X45)=5,SUM(H45,L45,P45,T45,X45),"") | Z45: =IF(Y45="","",Y45/5) | AA45: =IF(Z45="","",IF(ROUND(Z45,0)>=9,"ممتاز",IF(ROUND(Z45,0)>=7,"جيد جدا",IF(ROUND(Z45,0)>=5,"جيد",IF(ROUND(Z45,0)>=3,"مقبول","ضعيف"))))) | AB45: =IF(COUNT(G45,K45,O45)=3,SUM(G45,K45,O45),"") | AC45: =IF(Y45="","",1+COUNTIF($Y$6:$Y$45,">"&Y45)+COUNTIFS($Y$6:$Y$45,Y45,$AB$6:$AB$45,">"&AB45))
A47: تعليمات: صف «مثال» لا يدخل في الترتيب. أدخل عدّات الحكمين أو المحاولات في الخلايا الصفراء فقط. الاختبارات الزمنية: سجّل الزمن النهائي بعد إضافة ثواني العقوبات، واترك المحاولة الفاشلة فارغة. التعادل في الترتيب يُحسم بمجموع العدّات ثم الأقل زمناً/الأكبر مسافة ثم الأصغر سناً (يدوياً).

Sheet اختبارات ثانوي بنين
A1: سجل اختبارات اللياقة البدنية - ثانوي بنين
A2: المنطقة الأزهرية: .............. الإدارة التعليمية: .............. المعهد: .............. العام الدراسي: 2026/2027
A3: م | B3: الاسم | C3: تاريخ الميلاد | D3: الصف | E3: الجري في المكان (15ث) - عدد | I3: الجلوس من الرقود (30ث) - عدد | M3: الانبطاح المائل - عدد | Q3: الجري متعدد الجهات - زمن (ث) | U3: ثني الجذع من الوقوف - سم | Y3: إجمالي الدرجات | Z3: متوسط الدرجة (من 10) | AA3: التقدير | AB3: مجموع عدّات (الجري+الجلوس+الانبطاح) | AC3: الترتيب
E4: حكم 1 | F4: حكم 2 | G4: المتوسط | H4: الدرجة | I4: حكم 1 | J4: حكم 2 | K4: المتوسط | L4: الدرجة | M4: حكم 1 | N4: حكم 2 | O4: المتوسط | P4: الدرجة | Q4: محاولة 1 | R4: محاولة 2 | S4: الأفضل | T4: الدرجة | U4: محاولة 1 | V4: محاولة 2 | W4: الأفضل | X4: الدرجة
A5: مثال | B5: طالب (مثال) | C5: 2015-03-10 | D5: الثاني | E5: 30 | F5: 31 | G5: =IF(COUNT(E5:F5)=0,"",AVERAGE(E5:F5)) -> 30.5 | H5: =IF(G5="","",SUMPRODUCT(--(G5>=المساطر!$B$34:$B$43))) -> 5 | I5: 29 | J5: 29 | K5: =IF(COUNT(I5:J5)=0,"",AVERAGE(I5:J5)) -> 29 | L5: =IF(K5="","",SUMPRODUCT(--(K5>=المساطر!$C$34:$C$43))) -> 5 | M5: 46 | N5: 47 | O5: =IF(COUNT(M5:N5)=0,"",AVERAGE(M5:N5)) -> 46.5 | P5: =IF(O5="","",SUMPRODUCT(--(O5>=المساطر!$D$34:$D$43))) -> 7 | Q5: 13.9 | R5: 13.6 | S5: =IF(COUNT(Q5:R5)=0,"",MIN(Q5:R5)) -> 13.6 | T5: =IF(S5="","",SUMPRODUCT(--(S5<=المساطر!$E$34:$E$43))) -> 7 | U5: 12 | W5: =IF(COUNT(U5:V5)=0,"",MAX(U5:V5)) -> 12 | X5: =IF(W5="","",SUMPRODUCT(--(W5>=المساطر!$F$34:$F$43))) -> 6 | Y5: =IF(COUNT(H5,L5,P5,T5,X5)=5,SUM(H5,L5,P5,T5,X5),"") -> 30 | Z5: =IF(Y5="","",Y5/5) -> 6 | AA5: =IF(Z5="","",IF(ROUND(Z5,0)>=9,"ممتاز",IF(ROUND(Z5,0)>=7,"جيد جدا",IF(ROUND(Z5,0)>=5,"جيد",IF(ROUND(Z5,0)>=3,"مقبول","ضعيف"))))) -> جيد | AB5: =IF(COUNT(G5,K5,O5)=3,SUM(G5,K5,O5),"") -> 106 | AC5: =IF(Y5="","",1+COUNTIF($Y$6:$Y$45,">"&Y5)+COUNTIFS($Y$6:$Y$45,Y5,$AB$6:$AB$45,">"&AB5)) -> 1
A6: 1 | G6: =IF(COUNT(E6:F6)=0,"",AVERAGE(E6:F6)) | H6: =IF(G6="","",SUMPRODUCT(--(G6>=المساطر!$B$34:$B$43))) | K6: =IF(COUNT(I6:J6)=0,"",AVERAGE(I6:J6)) | L6: =IF(K6="","",SUMPRODUCT(--(K6>=المساطر!$C$34:$C$43))) | O6: =IF(COUNT(M6:N6)=0,"",AVERAGE(M6:N6)) | P6: =IF(O6="","",SUMPRODUCT(--(O6>=المساطر!$D$34:$D$43))) | S6: =IF(COUNT(Q6:R6)=0,"",MIN(Q6:R6)) | T6: =IF(S6="","",SUMPRODUCT(--(S6<=المساطر!$E$34:$E$43))) | W6: =IF(COUNT(U6:V6)=0,"",MAX(U6:V6)) | X6: =IF(W6="","",SUMPRODUCT(--(W6>=المساطر!$F$34:$F$43))) | Y6: =IF(COUNT(H6,L6,P6,T6,X6)=5,SUM(H6,L6,P6,T6,X6),"") | Z6: =IF(Y6="","",Y6/5) | AA6: =IF(Z6="","",IF(ROUND(Z6,0)>=9,"ممتاز",IF(ROUND(Z6,0)>=7,"جيد جدا",IF(ROUND(Z6,0)>=5,"جيد",IF(ROUND(Z6,0)>=3,"مقبول","ضعيف"))))) | AB6: =IF(COUNT(G6,K6,O6)=3,SUM(G6,K6,O6),"") | AC6: =IF(Y6="","",1+COUNTIF($Y$6:$Y$45,">"&Y6)+COUNTIFS($Y$6:$Y$45,Y6,$AB$6:$AB$45,">"&AB6))
A7: 2 | G7: =IF(COUNT(E7:F7)=0,"",AVERAGE(E7:F7)) | H7: =IF(G7="","",SUMPRODUCT(--(G7>=المساطر!$B$34:$B$43))) | K7: =IF(COUNT(I7:J7)=0,"",AVERAGE(I7:J7)) | L7: =IF(K7="","",SUMPRODUCT(--(K7>=المساطر!$C$34:$C$43))) | O7: =IF(COUNT(M7:N7)=0,"",AVERAGE(M7:N7)) | P7: =IF(O7="","",SUMPRODUCT(--(O7>=المساطر!$D$34:$D$43))) | S7: =IF(COUNT(Q7:R7)=0,"",MIN(Q7:R7)) | T7: =IF(S7="","",SUMPRODUCT(--(S7<=المساطر!$E$34:$E$43))) | W7: =IF(COUNT(U7:V7)=0,"",MAX(U7:V7)) | X7: =IF(W7="","",SUMPRODUCT(--(W7>=المساطر!$F$34:$F$43))) | Y7: =IF(COUNT(H7,L7,P7,T7,X7)=5,SUM(H7,L7,P7,T7,X7),"") | Z7: =IF(Y7="","",Y7/5) | AA7: =IF(Z7="","",IF(ROUND(Z7,0)>=9,"ممتاز",IF(ROUND(Z7,0)>=7,"جيد جدا",IF(ROUND(Z7,0)>=5,"جيد",IF(ROUND(Z7,0)>=3,"مقبول","ضعيف"))))) | AB7: =IF(COUNT(G7,K7,O7)=3,SUM(G7,K7,O7),"") | AC7: =IF(Y7="","",1+COUNTIF($Y$6:$Y$45,">"&Y7)+COUNTIFS($Y$6:$Y$45,Y7,$AB$6:$AB$45,">"&AB7))
A8: 3 | G8: =IF(COUNT(E8:F8)=0,"",AVERAGE(E8:F8)) | H8: =IF(G8="","",SUMPRODUCT(--(G8>=المساطر!$B$34:$B$43))) | K8: =IF(COUNT(I8:J8)=0,"",AVERAGE(I8:J8)) | L8: =IF(K8="","",SUMPRODUCT(--(K8>=المساطر!$C$34:$C$43))) | O8: =IF(COUNT(M8:N8)=0,"",AVERAGE(M8:N8)) | P8: =IF(O8="","",SUMPRODUCT(--(O8>=المساطر!$D$34:$D$43))) | S8: =IF(COUNT(Q8:R8)=0,"",MIN(Q8:R8)) | T8: =IF(S8="","",SUMPRODUCT(--(S8<=المساطر!$E$34:$E$43))) | W8: =IF(COUNT(U8:V8)=0,"",MAX(U8:V8)) | X8: =IF(W8="","",SUMPRODUCT(--(W8>=المساطر!$F$34:$F$43))) | Y8: =IF(COUNT(H8,L8,P8,T8,X8)=5,SUM(H8,L8,P8,T8,X8),"") | Z8: =IF(Y8="","",Y8/5) | AA8: =IF(Z8="","",IF(ROUND(Z8,0)>=9,"ممتاز",IF(ROUND(Z8,0)>=7,"جيد جدا",IF(ROUND(Z8,0)>=5,"جيد",IF(ROUND(Z8,0)>=3,"مقبول","ضعيف"))))) | AB8: =IF(COUNT(G8,K8,O8)=3,SUM(G8,K8,O8),"") | AC8: =IF(Y8="","",1+COUNTIF($Y$6:$Y$45,">"&Y8)+COUNTIFS($Y$6:$Y$45,Y8,$AB$6:$AB$45,">"&AB8))
A9: 4 | G9: =IF(COUNT(E9:F9)=0,"",AVERAGE(E9:F9)) | H9: =IF(G9="","",SUMPRODUCT(--(G9>=المساطر!$B$34:$B$43))) | K9: =IF(COUNT(I9:J9)=0,"",AVERAGE(I9:J9)) | L9: =IF(K9="","",SUMPRODUCT(--(K9>=المساطر!$C$34:$C$43))) | O9: =IF(COUNT(M9:N9)=0,"",AVERAGE(M9:N9)) | P9: =IF(O9="","",SUMPRODUCT(--(O9>=المساطر!$D$34:$D$43))) | S9: =IF(COUNT(Q9:R9)=0,"",MIN(Q9:R9)) | T9: =IF(S9="","",SUMPRODUCT(--(S9<=المساطر!$E$34:$E$43))) | W9: =IF(COUNT(U9:V9)=0,"",MAX(U9:V9)) | X9: =IF(W9="","",SUMPRODUCT(--(W9>=المساطر!$F$34:$F$43))) | Y9: =IF(COUNT(H9,L9,P9,T9,X9)=5,SUM(H9,L9,P9,T9,X9),"") | Z9: =IF(Y9="","",Y9/5) | AA9: =IF(Z9="","",IF(ROUND(Z9,0)>=9,"ممتاز",IF(ROUND(Z9,0)>=7,"جيد جدا",IF(ROUND(Z9,0)>=5,"جيد",IF(ROUND(Z9,0)>=3,"مقبول","ضعيف"))))) | AB9: =IF(COUNT(G9,K9,O9)=3,SUM(G9,K9,O9),"") | AC9: =IF(Y9="","",1+COUNTIF($Y$6:$Y$45,">"&Y9)+COUNTIFS($Y$6:$Y$45,Y9,$AB$6:$AB$45,">"&AB9))
A10: 5 | G10: =IF(COUNT(E10:F10)=0,"",AVERAGE(E10:F10)) | H10: =IF(G10="","",SUMPRODUCT(--(G10>=المساطر!$B$34:$B$43))) | K10: =IF(COUNT(I10:J10)=0,"",AVERAGE(I10:J10)) | L10: =IF(K10="","",SUMPRODUCT(--(K10>=المساطر!$C$34:$C$43))) | O10: =IF(COUNT(M10:N10)=0,"",AVERAGE(M10:N10)) | P10: =IF(O10="","",SUMPRODUCT(--(O10>=المساطر!$D$34:$D$43))) | S10: =IF(COUNT(Q10:R10)=0,"",MIN(Q10:R10)) | T10: =IF(S10="","",SUMPRODUCT(--(S10<=المساطر!$E$34:$E$43))) | W10: =IF(COUNT(U10:V10)=0,"",MAX(U10:V10)) | X10: =IF(W10="","",SUMPRODUCT(--(W10>=المساطر!$F$34:$F$43))) | Y10: =IF(COUNT(H10,L10,P10,T10,X10)=5,SUM(H10,L10,P10,T10,X10),"") | Z10: =IF(Y10="","",Y10/5) | AA10: =IF(Z10="","",IF(ROUND(Z10,0)>=9,"ممتاز",IF(ROUND(Z10,0)>=7,"جيد جدا",IF(ROUND(Z10,0)>=5,"جيد",IF(ROUND(Z10,0)>=3,"مقبول","ضعيف"))))) | AB10: =IF(COUNT(G10,K10,O10)=3,SUM(G10,K10,O10),"") | AC10: =IF(Y10="","",1+COUNTIF($Y$6:$Y$45,">"&Y10)+COUNTIFS($Y$6:$Y$45,Y10,$AB$6:$AB$45,">"&AB10))
A11: 6 | G11: =IF(COUNT(E11:F11)=0,"",AVERAGE(E11:F11)) | H11: =IF(G11="","",SUMPRODUCT(--(G11>=المساطر!$B$34:$B$43))) | K11: =IF(COUNT(I11:J11)=0,"",AVERAGE(I11:J11)) | L11: =IF(K11="","",SUMPRODUCT(--(K11>=المساطر!$C$34:$C$43))) | O11: =IF(COUNT(M11:N11)=0,"",AVERAGE(M11:N11)) | P11: =IF(O11="","",SUMPRODUCT(--(O11>=المساطر!$D$34:$D$43))) | S11: =IF(COUNT(Q11:R11)=0,"",MIN(Q11:R11)) | T11: =IF(S11="","",SUMPRODUCT(--(S11<=المساطر!$E$34:$E$43))) | W11: =IF(COUNT(U11:V11)=0,"",MAX(U11:V11)) | X11: =IF(W11="","",SUMPRODUCT(--(W11>=المساطر!$F$34:$F$43))) | Y11: =IF(COUNT(H11,L11,P11,T11,X11)=5,SUM(H11,L11,P11,T11,X11),"") | Z11: =IF(Y11="","",Y11/5) | AA11: =IF(Z11="","",IF(ROUND(Z11,0)>=9,"ممتاز",IF(ROUND(Z11,0)>=7,"جيد جدا",IF(ROUND(Z11,0)>=5,"جيد",IF(ROUND(Z11,0)>=3,"مقبول","ضعيف"))))) | AB11: =IF(COUNT(G11,K11,O11)=3,SUM(G11,K11,O11),"") | AC11: =IF(Y11="","",1+COUNTIF($Y$6:$Y$45,">"&Y11)+COUNTIFS($Y$6:$Y$45,Y11,$AB$6:$AB$45,">"&AB11))
A12: 7 | G12: =IF(COUNT(E12:F12)=0,"",AVERAGE(E12:F12)) | H12: =IF(G12="","",SUMPRODUCT(--(G12>=المساطر!$B$34:$B$43))) | K12: =IF(COUNT(I12:J12)=0,"",AVERAGE(I12:J12)) | L12: =IF(K12="","",SUMPRODUCT(--(K12>=المساطر!$C$34:$C$43))) | O12: =IF(COUNT(M12:N12)=0,"",AVERAGE(M12:N12)) | P12: =IF(O12="","",SUMPRODUCT(--(O12>=المساطر!$D$34:$D$43))) | S12: =IF(COUNT(Q12:R12)=0,"",MIN(Q12:R12)) | T12: =IF(S12="","",SUMPRODUCT(--(S12<=المساطر!$E$34:$E$43))) | W12: =IF(COUNT(U12:V12)=0,"",MAX(U12:V12)) | X12: =IF(W12="","",SUMPRODUCT(--(W12>=المساطر!$F$34:$F$43))) | Y12: =IF(COUNT(H12,L12,P12,T12,X12)=5,SUM(H12,L12,P12,T12,X12),"") | Z12: =IF(Y12="","",Y12/5) | AA12: =IF(Z12="","",IF(ROUND(Z12,0)>=9,"ممتاز",IF(ROUND(Z12,0)>=7,"جيد جدا",IF(ROUND(Z12,0)>=5,"جيد",IF(ROUND(Z12,0)>=3,"مقبول","ضعيف"))))) | AB12: =IF(COUNT(G12,K12,O12)=3,SUM(G12,K12,O12),"") | AC12: =IF(Y12="","",1+COUNTIF($Y$6:$Y$45,">"&Y12)+COUNTIFS($Y$6:$Y$45,Y12,$AB$6:$AB$45,">"&AB12))
A13: 8 | G13: =IF(COUNT(E13:F13)=0,"",AVERAGE(E13:F13)) | H13: =IF(G13="","",SUMPRODUCT(--(G13>=المساطر!$B$34:$B$43))) | K13: =IF(COUNT(I13:J13)=0,"",AVERAGE(I13:J13)) | L13: =IF(K13="","",SUMPRODUCT(--(K13>=المساطر!$C$34:$C$43))) | O13: =IF(COUNT(M13:N13)=0,"",AVERAGE(M13:N13)) | P13: =IF(O13="","",SUMPRODUCT(--(O13>=المساطر!$D$34:$D$43))) | S13: =IF(COUNT(Q13:R13)=0,"",MIN(Q13:R13)) | T13: =IF(S13="","",SUMPRODUCT(--(S13<=المساطر!$E$34:$E$43))) | W13: =IF(COUNT(U13:V13)=0,"",MAX(U13:V13)) | X13: =IF(W13="","",SUMPRODUCT(--(W13>=المساطر!$F$34:$F$43))) | Y13: =IF(COUNT(H13,L13,P13,T13,X13)=5,SUM(H13,L13,P13,T13,X13),"") | Z13: =IF(Y13="","",Y13/5) | AA13: =IF(Z13="","",IF(ROUND(Z13,0)>=9,"ممتاز",IF(ROUND(Z13,0)>=7,"جيد جدا",IF(ROUND(Z13,0)>=5,"جيد",IF(ROUND(Z13,0)>=3,"مقبول","ضعيف"))))) | AB13: =IF(COUNT(G13,K13,O13)=3,SUM(G13,K13,O13),"") | AC13: =IF(Y13="","",1+COUNTIF($Y$6:$Y$45,">"&Y13)+COUNTIFS($Y$6:$Y$45,Y13,$AB$6:$AB$45,">"&AB13))
A14: 9 | G14: =IF(COUNT(E14:F14)=0,"",AVERAGE(E14:F14)) | H14: =IF(G14="","",SUMPRODUCT(--(G14>=المساطر!$B$34:$B$43))) | K14: =IF(COUNT(I14:J14)=0,"",AVERAGE(I14:J14)) | L14: =IF(K14="","",SUMPRODUCT(--(K14>=المساطر!$C$34:$C$43))) | O14: =IF(COUNT(M14:N14)=0,"",AVERAGE(M14:N14)) | P14: =IF(O14="","",SUMPRODUCT(--(O14>=المساطر!$D$34:$D$43))) | S14: =IF(COUNT(Q14:R14)=0,"",MIN(Q14:R14)) | T14: =IF(S14="","",SUMPRODUCT(--(S14<=المساطر!$E$34:$E$43))) | W14: =IF(COUNT(U14:V14)=0,"",MAX(U14:V14)) | X14: =IF(W14="","",SUMPRODUCT(--(W14>=المساطر!$F$34:$F$43))) | Y14: =IF(COUNT(H14,L14,P14,T14,X14)=5,SUM(H14,L14,P14,T14,X14),"") | Z14: =IF(Y14="","",Y14/5) | AA14: =IF(Z14="","",IF(ROUND(Z14,0)>=9,"ممتاز",IF(ROUND(Z14,0)>=7,"جيد جدا",IF(ROUND(Z14,0)>=5,"جيد",IF(ROUND(Z14,0)>=3,"مقبول","ضعيف"))))) | AB14: =IF(COUNT(G14,K14,O14)=3,SUM(G14,K14,O14),"") | AC14: =IF(Y14="","",1+COUNTIF($Y$6:$Y$45,">"&Y14)+COUNTIFS($Y$6:$Y$45,Y14,$AB$6:$AB$45,">"&AB14))
A15: 10 | G15: =IF(COUNT(E15:F15)=0,"",AVERAGE(E15:F15)) | H15: =IF(G15="","",SUMPRODUCT(--(G15>=المساطر!$B$34:$B$43))) | K15: =IF(COUNT(I15:J15)=0,"",AVERAGE(I15:J15)) | L15: =IF(K15="","",SUMPRODUCT(--(K15>=المساطر!$C$34:$C$43))) | O15: =IF(COUNT(M15:N15)=0,"",AVERAGE(M15:N15)) | P15: =IF(O15="","",SUMPRODUCT(--(O15>=المساطر!$D$34:$D$43))) | S15: =IF(COUNT(Q15:R15)=0,"",MIN(Q15:R15)) | T15: =IF(S15="","",SUMPRODUCT(--(S15<=المساطر!$E$34:$E$43))) | W15: =IF(COUNT(U15:V15)=0,"",MAX(U15:V15)) | X15: =IF(W15="","",SUMPRODUCT(--(W15>=المساطر!$F$34:$F$43))) | Y15: =IF(COUNT(H15,L15,P15,T15,X15)=5,SUM(H15,L15,P15,T15,X15),"") | Z15: =IF(Y15="","",Y15/5) | AA15: =IF(Z15="","",IF(ROUND(Z15,0)>=9,"ممتاز",IF(ROUND(Z15,0)>=7,"جيد جدا",IF(ROUND(Z15,0)>=5,"جيد",IF(ROUND(Z15,0)>=3,"مقبول","ضعيف"))))) | AB15: =IF(COUNT(G15,K15,O15)=3,SUM(G15,K15,O15),"") | AC15: =IF(Y15="","",1+COUNTIF($Y$6:$Y$45,">"&Y15)+COUNTIFS($Y$6:$Y$45,Y15,$AB$6:$AB$45,">"&AB15))
A16: 11 | G16: =IF(COUNT(E16:F16)=0,"",AVERAGE(E16:F16)) | H16: =IF(G16="","",SUMPRODUCT(--(G16>=المساطر!$B$34:$B$43))) | K16: =IF(COUNT(I16:J16)=0,"",AVERAGE(I16:J16)) | L16: =IF(K16="","",SUMPRODUCT(--(K16>=المساطر!$C$34:$C$43))) | O16: =IF(COUNT(M16:N16)=0,"",AVERAGE(M16:N16)) | P16: =IF(O16="","",SUMPRODUCT(--(O16>=المساطر!$D$34:$D$43))) | S16: =IF(COUNT(Q16:R16)=0,"",MIN(Q16:R16)) | T16: =IF(S16="","",SUMPRODUCT(--(S16<=المساطر!$E$34:$E$43))) | W16: =IF(COUNT(U16:V16)=0,"",MAX(U16:V16)) | X16: =IF(W16="","",SUMPRODUCT(--(W16>=المساطر!$F$34:$F$43))) | Y16: =IF(COUNT(H16,L16,P16,T16,X16)=5,SUM(H16,L16,P16,T16,X16),"") | Z16: =IF(Y16="","",Y16/5) | AA16: =IF(Z16="","",IF(ROUND(Z16,0)>=9,"ممتاز",IF(ROUND(Z16,0)>=7,"جيد جدا",IF(ROUND(Z16,0)>=5,"جيد",IF(ROUND(Z16,0)>=3,"مقبول","ضعيف"))))) | AB16: =IF(COUNT(G16,K16,O16)=3,SUM(G16,K16,O16),"") | AC16: =IF(Y16="","",1+COUNTIF($Y$6:$Y$45,">"&Y16)+COUNTIFS($Y$6:$Y$45,Y16,$AB$6:$AB$45,">"&AB16))
A17: 12 | G17: =IF(COUNT(E17:F17)=0,"",AVERAGE(E17:F17)) | H17: =IF(G17="","",SUMPRODUCT(--(G17>=المساطر!$B$34:$B$43))) | K17: =IF(COUNT(I17:J17)=0,"",AVERAGE(I17:J17)) | L17: =IF(K17="","",SUMPRODUCT(--(K17>=المساطر!$C$34:$C$43))) | O17: =IF(COUNT(M17:N17)=0,"",AVERAGE(M17:N17)) | P17: =IF(O17="","",SUMPRODUCT(--(O17>=المساطر!$D$34:$D$43))) | S17: =IF(COUNT(Q17:R17)=0,"",MIN(Q17:R17)) | T17: =IF(S17="","",SUMPRODUCT(--(S17<=المساطر!$E$34:$E$43))) | W17: =IF(COUNT(U17:V17)=0,"",MAX(U17:V17)) | X17: =IF(W17="","",SUMPRODUCT(--(W17>=المساطر!$F$34:$F$43))) | Y17: =IF(COUNT(H17,L17,P17,T17,X17)=5,SUM(H17,L17,P17,T17,X17),"") | Z17: =IF(Y17="","",Y17/5) | AA17: =IF(Z17="","",IF(ROUND(Z17,0)>=9,"ممتاز",IF(ROUND(Z17,0)>=7,"جيد جدا",IF(ROUND(Z17,0)>=5,"جيد",IF(ROUND(Z17,0)>=3,"مقبول","ضعيف"))))) | AB17: =IF(COUNT(G17,K17,O17)=3,SUM(G17,K17,O17),"") | AC17: =IF(Y17="","",1+COUNTIF($Y$6:$Y$45,">"&Y17)+COUNTIFS($Y$6:$Y$45,Y17,$AB$6:$AB$45,">"&AB17))
... A45: 40 | G45: =IF(COUNT(E45:F45)=0,"",AVERAGE(E45:F45)) | H45: =IF(G45="","",SUMPRODUCT(--(G45>=المساطر!$B$34:$B$43))) | K45: =IF(COUNT(I45:J45)=0,"",AVERAGE(I45:J45)) | L45: =IF(K45="","",SUMPRODUCT(--(K45>=المساطر!$C$34:$C$43))) | O45: =IF(COUNT(M45:N45)=0,"",AVERAGE(M45:N45)) | P45: =IF(O45="","",SUMPRODUCT(--(O45>=المساطر!$D$34:$D$43))) | S45: =IF(COUNT(Q45:R45)=0,"",MIN(Q45:R45)) | T45: =IF(S45="","",SUMPRODUCT(--(S45<=المساطر!$E$34:$E$43))) | W45: =IF(COUNT(U45:V45)=0,"",MAX(U45:V45)) | X45: =IF(W45="","",SUMPRODUCT(--(W45>=المساطر!$F$34:$F$43))) | Y45: =IF(COUNT(H45,L45,P45,T45,X45)=5,SUM(H45,L45,P45,T45,X45),"") | Z45: =IF(Y45="","",Y45/5) | AA45: =IF(Z45="","",IF(ROUND(Z45,0)>=9,"ممتاز",IF(ROUND(Z45,0)>=7,"جيد جدا",IF(ROUND(Z45,0)>=5,"جيد",IF(ROUND(Z45,0)>=3,"مقبول","ضعيف"))))) | AB45: =IF(COUNT(G45,K45,O45)=3,SUM(G45,K45,O45),"") | AC45: =IF(Y45="","",1+COUNTIF($Y$6:$Y$45,">"&Y45)+COUNTIFS($Y$6:$Y$45,Y45,$AB$6:$AB$45,">"&AB45))
A47: تعليمات: صف «مثال» لا يدخل في الترتيب. أدخل عدّات الحكمين أو المحاولات في الخلايا الصفراء فقط. الاختبارات الزمنية: سجّل الزمن النهائي بعد إضافة ثواني العقوبات، واترك المحاولة الفاشلة فارغة. التعادل في الترتيب يُحسم بمجموع العدّات ثم الأقل زمناً/الأكبر مسافة ثم الأصغر سناً (يدوياً).

Sheet اختبارات ابتدائي بنات
A1: سجل المسح الشامل واختبارات اللياقة البدنية - ابتدائي بنات
A2: المنطقة الأزهرية: .............. الإدارة التعليمية: .............. المعهد: .............. العام الدراسي: 2026/2027
A3: م | B3: الاسم | C3: تاريخ الميلاد | D3: الصف | E3: الجري في المكان (15ث) - عدد | I3: الجلوس من الرقود (30ث) - عدد | M3: الانبطاح المائل العالي - عدد | Q3: الجري الارتدادي - زمن (ث) | U3: الوثب داخل الدوائر المرقمة - زمن (ث) | Y3: إجمالي الدرجات | Z3: متوسط الدرجة (من 10) | AA3: التقدير | AB3: مجموع عدّات (الجري+الجلوس+الانبطاح) | AC3: الترتيب
E4: حكم 1 | F4: حكم 2 | G4: المتوسط | H4: الدرجة | I4: حكم 1 | J4: حكم 2 | K4: المتوسط | L4: الدرجة | M4: حكم 1 | N4: حكم 2 | O4: المتوسط | P4: الدرجة | Q4: محاولة 1 | R4: محاولة 2 | S4: الأفضل | T4: الدرجة | U4: محاولة 1 | V4: محاولة 2 | W4: الأفضل | X4: الدرجة
A5: مثال | B5: طالب (مثال) | C5: 2015-03-10 | D5: الثاني | E5: 20 | F5: 21 | G5: =IF(COUNT(E5:F5)=0,"",AVERAGE(E5:F5)) -> 20.5 | H5: =IF(G5="","",SUMPRODUCT(--(G5>=المساطر!$B$48:$B$57))) -> 5 | I5: 18 | J5: 18 | K5: =IF(COUNT(I5:J5)=0,"",AVERAGE(I5:J5)) -> 18 | L5: =IF(K5="","",SUMPRODUCT(--(K5>=المساطر!$C$48:$C$57))) -> 5 | M5: 26 | N5: 27 | O5: =IF(COUNT(M5:N5)=0,"",AVERAGE(M5:N5)) -> 26.5 | P5: =IF(O5="","",SUMPRODUCT(--(O5>=المساطر!$D$48:$D$57))) -> 4 | Q5: 12.8 | R5: 12.4 | S5: =IF(COUNT(Q5:R5)=0,"",MIN(Q5:R5)) -> 12.4 | T5: =IF(S5="","",SUMPRODUCT(--(S5<=المساطر!$E$48:$E$57))) -> 6 | U5: 7.5 | V5: 7.2 | W5: =IF(COUNT(U5:V5)=0,"",MIN(U5:V5)) -> 7.2 | X5: =IF(W5="","",SUMPRODUCT(--(W5<=المساطر!$F$48:$F$57))) -> 5 | Y5: =IF(COUNT(H5,L5,P5,T5,X5)=5,SUM(H5,L5,P5,T5,X5),"") -> 25 | Z5: =IF(Y5="","",Y5/5) -> 5 | AA5: =IF(Z5="","",IF(ROUND(Z5,0)>=9,"ممتاز",IF(ROUND(Z5,0)>=7,"جيد جدا",IF(ROUND(Z5,0)>=5,"جيد",IF(ROUND(Z5,0)>=3,"مقبول","ضعيف"))))) -> جيد | AB5: =IF(COUNT(G5,K5,O5)=3,SUM(G5,K5,O5),"") -> 65 | AC5: =IF(Y5="","",1+COUNTIF($Y$6:$Y$45,">"&Y5)+COUNTIFS($Y$6:$Y$45,Y5,$AB$6:$AB$45,">"&AB5)) -> 1
A6: 1 | G6: =IF(COUNT(E6:F6)=0,"",AVERAGE(E6:F6)) | H6: =IF(G6="","",SUMPRODUCT(--(G6>=المساطر!$B$48:$B$57))) | K6: =IF(COUNT(I6:J6)=0,"",AVERAGE(I6:J6)) | L6: =IF(K6="","",SUMPRODUCT(--(K6>=المساطر!$C$48:$C$57))) | O6: =IF(COUNT(M6:N6)=0,"",AVERAGE(M6:N6)) | P6: =IF(O6="","",SUMPRODUCT(--(O6>=المساطر!$D$48:$D$57))) | Q6: 12.99 | S6: =IF(COUNT(Q6:R6)=0,"",MIN(Q6:R6)) -> 12.99 | T6: =IF(S6="","",SUMPRODUCT(--(S6<=المساطر!$E$48:$E$57))) -> 5 | W6: =IF(COUNT(U6:V6)=0,"",MIN(U6:V6)) | X6: =IF(W6="","",SUMPRODUCT(--(W6<=المساطر!$F$48:$F$57))) | Y6: =IF(COUNT(H6,L6,P6,T6,X6)=5,SUM(H6,L6,P6,T6,X6),"") | Z6: =IF(Y6="","",Y6/5) | AA6: =IF(Z6="","",IF(ROUND(Z6,0)>=9,"ممتاز",IF(ROUND(Z6,0)>=7,"جيد جدا",IF(ROUND(Z6,0)>=5,"جيد",IF(ROUND(Z6,0)>=3,"مقبول","ضعيف"))))) | AB6: =IF(COUNT(G6,K6,O6)=3,SUM(G6,K6,O6),"") | AC6: =IF(Y6="","",1+COUNTIF($Y$6:$Y$45,">"&Y6)+COUNTIFS($Y$6:$Y$45,Y6,$AB$6:$AB$45,">"&AB6))
A7: 2 | G7: =IF(COUNT(E7:F7)=0,"",AVERAGE(E7:F7)) | H7: =IF(G7="","",SUMPRODUCT(--(G7>=المساطر!$B$48:$B$57))) | K7: =IF(COUNT(I7:J7)=0,"",AVERAGE(I7:J7)) | L7: =IF(K7="","",SUMPRODUCT(--(K7>=المساطر!$C$48:$C$57))) | O7: =IF(COUNT(M7:N7)=0,"",AVERAGE(M7:N7)) | P7: =IF(O7="","",SUMPRODUCT(--(O7>=المساطر!$D$48:$D$57))) | S7: =IF(COUNT(Q7:R7)=0,"",MIN(Q7:R7)) | T7: =IF(S7="","",SUMPRODUCT(--(S7<=المساطر!$E$48:$E$57))) | W7: =IF(COUNT(U7:V7)=0,"",MIN(U7:V7)) | X7: =IF(W7="","",SUMPRODUCT(--(W7<=المساطر!$F$48:$F$57))) | Y7: =IF(COUNT(H7,L7,P7,T7,X7)=5,SUM(H7,L7,P7,T7,X7),"") | Z7: =IF(Y7="","",Y7/5) | AA7: =IF(Z7="","",IF(ROUND(Z7,0)>=9,"ممتاز",IF(ROUND(Z7,0)>=7,"جيد جدا",IF(ROUND(Z7,0)>=5,"جيد",IF(ROUND(Z7,0)>=3,"مقبول","ضعيف"))))) | AB7: =IF(COUNT(G7,K7,O7)=3,SUM(G7,K7,O7),"") | AC7: =IF(Y7="","",1+COUNTIF($Y$6:$Y$45,">"&Y7)+COUNTIFS($Y$6:$Y$45,Y7,$AB$6:$AB$45,">"&AB7))
A8: 3 | G8: =IF(COUNT(E8:F8)=0,"",AVERAGE(E8:F8)) | H8: =IF(G8="","",SUMPRODUCT(--(G8>=المساطر!$B$48:$B$57))) | K8: =IF(COUNT(I8:J8)=0,"",AVERAGE(I8:J8)) | L8: =IF(K8="","",SUMPRODUCT(--(K8>=المساطر!$C$48:$C$57))) | O8: =IF(COUNT(M8:N8)=0,"",AVERAGE(M8:N8)) | P8: =IF(O8="","",SUMPRODUCT(--(O8>=المساطر!$D$48:$D$57))) | S8: =IF(COUNT(Q8:R8)=0,"",MIN(Q8:R8)) | T8: =IF(S8="","",SUMPRODUCT(--(S8<=المساطر!$E$48:$E$57))) | W8: =IF(COUNT(U8:V8)=0,"",MIN(U8:V8)) | X8: =IF(W8="","",SUMPRODUCT(--(W8<=المساطر!$F$48:$F$57))) | Y8: =IF(COUNT(H8,L8,P8,T8,X8)=5,SUM(H8,L8,P8,T8,X8),"") | Z8: =IF(Y8="","",Y8/5) | AA8: =IF(Z8="","",IF(ROUND(Z8,0)>=9,"ممتاز",IF(ROUND(Z8,0)>=7,"جيد جدا",IF(ROUND(Z8,0)>=5,"جيد",IF(ROUND(Z8,0)>=3,"مقبول","ضعيف"))))) | AB8: =IF(COUNT(G8,K8,O8)=3,SUM(G8,K8,O8),"") | AC8: =IF(Y8="","",1+COUNTIF($Y$6:$Y$45,">"&Y8)+COUNTIFS($Y$6:$Y$45,Y8,$AB$6:$AB$45,">"&AB8))
A9: 4 | G9: =IF(COUNT(E9:F9)=0,"",AVERAGE(E9:F9)) | H9: =IF(G9="","",SUMPRODUCT(--(G9>=المساطر!$B$48:$B$57))) | K9: =IF(COUNT(I9:J9)=0,"",AVERAGE(I9:J9)) | L9: =IF(K9="","",SUMPRODUCT(--(K9>=المساطر!$C$48:$C$57))) | O9: =IF(COUNT(M9:N9)=0,"",AVERAGE(M9:N9)) | P9: =IF(O9="","",SUMPRODUCT(--(O9>=المساطر!$D$48:$D$57))) | S9: =IF(COUNT(Q9:R9)=0,"",MIN(Q9:R9)) | T9: =IF(S9="","",SUMPRODUCT(--(S9<=المساطر!$E$48:$E$57))) | W9: =IF(COUNT(U9:V9)=0,"",MIN(U9:V9)) | X9: =IF(W9="","",SUMPRODUCT(--(W9<=المساطر!$F$48:$F$57))) | Y9: =IF(COUNT(H9,L9,P9,T9,X9)=5,SUM(H9,L9,P9,T9,X9),"") | Z9: =IF(Y9="","",Y9/5) | AA9: =IF(Z9="","",IF(ROUND(Z9,0)>=9,"ممتاز",IF(ROUND(Z9,0)>=7,"جيد جدا",IF(ROUND(Z9,0)>=5,"جيد",IF(ROUND(Z9,0)>=3,"مقبول","ضعيف"))))) | AB9: =IF(COUNT(G9,K9,O9)=3,SUM(G9,K9,O9),"") | AC9: =IF(Y9="","",1+COUNTIF($Y$6:$Y$45,">"&Y9)+COUNTIFS($Y$6:$Y$45,Y9,$AB$6:$AB$45,">"&AB9))
A10: 5 | G10: =IF(COUNT(E10:F10)=0,"",AVERAGE(E10:F10)) | H10: =IF(G10="","",SUMPRODUCT(--(G10>=المساطر!$B$48:$B$57))) | K10: =IF(COUNT(I10:J10)=0,"",AVERAGE(I10:J10)) | L10: =IF(K10="","",SUMPRODUCT(--(K10>=المساطر!$C$48:$C$57))) | O10: =IF(COUNT(M10:N10)=0,"",AVERAGE(M10:N10)) | P10: =IF(O10="","",SUMPRODUCT(--(O10>=المساطر!$D$48:$D$57))) | S10: =IF(COUNT(Q10:R10)=0,"",MIN(Q10:R10)) | T10: =IF(S10="","",SUMPRODUCT(--(S10<=المساطر!$E$48:$E$57))) | W10: =IF(COUNT(U10:V10)=0,"",MIN(U10:V10)) | X10: =IF(W10="","",SUMPRODUCT(--(W10<=المساطر!$F$48:$F$57))) | Y10: =IF(COUNT(H10,L10,P10,T10,X10)=5,SUM(H10,L10,P10,T10,X10),"") | Z10: =IF(Y10="","",Y10/5) | AA10: =IF(Z10="","",IF(ROUND(Z10,0)>=9,"ممتاز",IF(ROUND(Z10,0)>=7,"جيد جدا",IF(ROUND(Z10,0)>=5,"جيد",IF(ROUND(Z10,0)>=3,"مقبول","ضعيف"))))) | AB10: =IF(COUNT(G10,K10,O10)=3,SUM(G10,K10,O10),"") | AC10: =IF(Y10="","",1+COUNTIF($Y$6:$Y$45,">"&Y10)+COUNTIFS($Y$6:$Y$45,Y10,$AB$6:$AB$45,">"&AB10))
A11: 6 | G11: =IF(COUNT(E11:F11)=0,"",AVERAGE(E11:F11)) | H11: =IF(G11="","",SUMPRODUCT(--(G11>=المساطر!$B$48:$B$57))) | K11: =IF(COUNT(I11:J11)=0,"",AVERAGE(I11:J11)) | L11: =IF(K11="","",SUMPRODUCT(--(K11>=المساطر!$C$48:$C$57))) | O11: =IF(COUNT(M11:N11)=0,"",AVERAGE(M11:N11)) | P11: =IF(O11="","",SUMPRODUCT(--(O11>=المساطر!$D$48:$D$57))) | S11: =IF(COUNT(Q11:R11)=0,"",MIN(Q11:R11)) | T11: =IF(S11="","",SUMPRODUCT(--(S11<=المساطر!$E$48:$E$57))) | W11: =IF(COUNT(U11:V11)=0,"",MIN(U11:V11)) | X11: =IF(W11="","",SUMPRODUCT(--(W11<=المساطر!$F$48:$F$57))) | Y11: =IF(COUNT(H11,L11,P11,T11,X11)=5,SUM(H11,L11,P11,T11,X11),"") | Z11: =IF(Y11="","",Y11/5) | AA11: =IF(Z11="","",IF(ROUND(Z11,0)>=9,"ممتاز",IF(ROUND(Z11,0)>=7,"جيد جدا",IF(ROUND(Z11,0)>=5,"جيد",IF(ROUND(Z11,0)>=3,"مقبول","ضعيف"))))) | AB11: =IF(COUNT(G11,K11,O11)=3,SUM(G11,K11,O11),"") | AC11: =IF(Y11="","",1+COUNTIF($Y$6:$Y$45,">"&Y11)+COUNTIFS($Y$6:$Y$45,Y11,$AB$6:$AB$45,">"&AB11))
A12: 7 | G12: =IF(COUNT(E12:F12)=0,"",AVERAGE(E12:F12)) | H12: =IF(G12="","",SUMPRODUCT(--(G12>=المساطر!$B$48:$B$57))) | K12: =IF(COUNT(I12:J12)=0,"",AVERAGE(I12:J12)) | L12: =IF(K12="","",SUMPRODUCT(--(K12>=المساطر!$C$48:$C$57))) | O12: =IF(COUNT(M12:N12)=0,"",AVERAGE(M12:N12)) | P12: =IF(O12="","",SUMPRODUCT(--(O12>=المساطر!$D$48:$D$57))) | S12: =IF(COUNT(Q12:R12)=0,"",MIN(Q12:R12)) | T12: =IF(S12="","",SUMPRODUCT(--(S12<=المساطر!$E$48:$E$57))) | W12: =IF(COUNT(U12:V12)=0,"",MIN(U12:V12)) | X12: =IF(W12="","",SUMPRODUCT(--(W12<=المساطر!$F$48:$F$57))) | Y12: =IF(COUNT(H12,L12,P12,T12,X12)=5,SUM(H12,L12,P12,T12,X12),"") | Z12: =IF(Y12="","",Y12/5) | AA12: =IF(Z12="","",IF(ROUND(Z12,0)>=9,"ممتاز",IF(ROUND(Z12,0)>=7,"جيد جدا",IF(ROUND(Z12,0)>=5,"جيد",IF(ROUND(Z12,0)>=3,"مقبول","ضعيف"))))) | AB12: =IF(COUNT(G12,K12,O12)=3,SUM(G12,K12,O12),"") | AC12: =IF(Y12="","",1+COUNTIF($Y$6:$Y$45,">"&Y12)+COUNTIFS($Y$6:$Y$45,Y12,$AB$6:$AB$45,">"&AB12))
A13: 8 | G13: =IF(COUNT(E13:F13)=0,"",AVERAGE(E13:F13)) | H13: =IF(G13="","",SUMPRODUCT(--(G13>=المساطر!$B$48:$B$57))) | K13: =IF(COUNT(I13:J13)=0,"",AVERAGE(I13:J13)) | L13: =IF(K13="","",SUMPRODUCT(--(K13>=المساطر!$C$48:$C$57))) | O13: =IF(COUNT(M13:N13)=0,"",AVERAGE(M13:N13)) | P13: =IF(O13="","",SUMPRODUCT(--(O13>=المساطر!$D$48:$D$57))) | S13: =IF(COUNT(Q13:R13)=0,"",MIN(Q13:R13)) | T13: =IF(S13="","",SUMPRODUCT(--(S13<=المساطر!$E$48:$E$57))) | W13: =IF(COUNT(U13:V13)=0,"",MIN(U13:V13)) | X13: =IF(W13="","",SUMPRODUCT(--(W13<=المساطر!$F$48:$F$57))) | Y13: =IF(COUNT(H13,L13,P13,T13,X13)=5,SUM(H13,L13,P13,T13,X13),"") | Z13: =IF(Y13="","",Y13/5) | AA13: =IF(Z13="","",IF(ROUND(Z13,0)>=9,"ممتاز",IF(ROUND(Z13,0)>=7,"جيد جدا",IF(ROUND(Z13,0)>=5,"جيد",IF(ROUND(Z13,0)>=3,"مقبول","ضعيف"))))) | AB13: =IF(COUNT(G13,K13,O13)=3,SUM(G13,K13,O13),"") | AC13: =IF(Y13="","",1+COUNTIF($Y$6:$Y$45,">"&Y13)+COUNTIFS($Y$6:$Y$45,Y13,$AB$6:$AB$45,">"&AB13))
A14: 9 | G14: =IF(COUNT(E14:F14)=0,"",AVERAGE(E14:F14)) | H14: =IF(G14="","",SUMPRODUCT(--(G14>=المساطر!$B$48:$B$57))) | K14: =IF(COUNT(I14:J14)=0,"",AVERAGE(I14:J14)) | L14: =IF(K14="","",SUMPRODUCT(--(K14>=المساطر!$C$48:$C$57))) | O14: =IF(COUNT(M14:N14)=0,"",AVERAGE(M14:N14)) | P14: =IF(O14="","",SUMPRODUCT(--(O14>=المساطر!$D$48:$D$57))) | S14: =IF(COUNT(Q14:R14)=0,"",MIN(Q14:R14)) | T14: =IF(S14="","",SUMPRODUCT(--(S14<=المساطر!$E$48:$E$57))) | W14: =IF(COUNT(U14:V14)=0,"",MIN(U14:V14)) | X14: =IF(W14="","",SUMPRODUCT(--(W14<=المساطر!$F$48:$F$57))) | Y14: =IF(COUNT(H14,L14,P14,T14,X14)=5,SUM(H14,L14,P14,T14,X14),"") | Z14: =IF(Y14="","",Y14/5) | AA14: =IF(Z14="","",IF(ROUND(Z14,0)>=9,"ممتاز",IF(ROUND(Z14,0)>=7,"جيد جدا",IF(ROUND(Z14,0)>=5,"جيد",IF(ROUND(Z14,0)>=3,"مقبول","ضعيف"))))) | AB14: =IF(COUNT(G14,K14,O14)=3,SUM(G14,K14,O14),"") | AC14: =IF(Y14="","",1+COUNTIF($Y$6:$Y$45,">"&Y14)+COUNTIFS($Y$6:$Y$45,Y14,$AB$6:$AB$45,">"&AB14))
A15: 10 | G15: =IF(COUNT(E15:F15)=0,"",AVERAGE(E15:F15)) | H15: =IF(G15="","",SUMPRODUCT(--(G15>=المساطر!$B$48:$B$57))) | K15: =IF(COUNT(I15:J15)=0,"",AVERAGE(I15:J15)) | L15: =IF(K15="","",SUMPRODUCT(--(K15>=المساطر!$C$48:$C$57))) | O15: =IF(COUNT(M15:N15)=0,"",AVERAGE(M15:N15)) | P15: =IF(O15="","",SUMPRODUCT(--(O15>=المساطر!$D$48:$D$57))) | S15: =IF(COUNT(Q15:R15)=0,"",MIN(Q15:R15)) | T15: =IF(S15="","",SUMPRODUCT(--(S15<=المساطر!$E$48:$E$57))) | W15: =IF(COUNT(U15:V15)=0,"",MIN(U15:V15)) | X15: =IF(W15="","",SUMPRODUCT(--(W15<=المساطر!$F$48:$F$57))) | Y15: =IF(COUNT(H15,L15,P15,T15,X15)=5,SUM(H15,L15,P15,T15,X15),"") | Z15: =IF(Y15="","",Y15/5) | AA15: =IF(Z15="","",IF(ROUND(Z15,0)>=9,"ممتاز",IF(ROUND(Z15,0)>=7,"جيد جدا",IF(ROUND(Z15,0)>=5,"جيد",IF(ROUND(Z15,0)>=3,"مقبول","ضعيف"))))) | AB15: =IF(COUNT(G15,K15,O15)=3,SUM(G15,K15,O15),"") | AC15: =IF(Y15="","",1+COUNTIF($Y$6:$Y$45,">"&Y15)+COUNTIFS($Y$6:$Y$45,Y15,$AB$6:$AB$45,">"&AB15))
